22:21:48.464 INFO Test execution started: test_page/add_description
22:21:48.465 INFO Browser: chrome
22:21:48.465 INFO Environment: test
22:21:48.465 INFO Using data: 
    description: description of the test
    url: http://localhost:8000

22:21:50.544 INFO Navigate to: 'http://localhost:8000'
22:21:50.645 INFO Write 'admin' in element username
22:21:50.723 INFO Write 'admin' in element password
22:21:50.760 INFO Click login_button
22:21:51.206 INFO Random value generated: mjxixwm
22:21:51.206 INFO Store value mjxixwm in key name
22:22:12.073 INFO Write 'mjxixwm' in element None
22:22:12.073 INFO Press key: ENTER
22:22:12.170 INFO Click None
22:22:12.534 INFO Write 'description of the test' in element description
22:22:12.570 INFO Click save
22:22:12.746 INFO Refresh page
22:22:32.858 INFO Take screenshot error
22:22:32.860 ERROR An error ocurred:
Traceback (most recent call last):
  File "/Users/lucianofeo/Desktop/golem/src/golem/browser.py", line 19, in _find_webelement
    webelement = root.find_element_by_id(selector_value)
  File "/Users/lucianofeo/Desktop/golem/env/lib/python3.6/site-packages/selenium-3.6.0-py3.6.egg/selenium/webdriver/remote/webdriver.py", line 341, in find_element_by_id
    return self.find_element(by=By.ID, value=id_)
  File "/Users/lucianofeo/Desktop/golem/env/lib/python3.6/site-packages/selenium-3.6.0-py3.6.egg/selenium/webdriver/remote/webdriver.py", line 843, in find_element
    'value': value})['value']
  File "/Users/lucianofeo/Desktop/golem/env/lib/python3.6/site-packages/selenium-3.6.0-py3.6.egg/selenium/webdriver/remote/webdriver.py", line 308, in execute
    self.error_handler.check_response(response)
  File "/Users/lucianofeo/Desktop/golem/env/lib/python3.6/site-packages/selenium-3.6.0-py3.6.egg/selenium/webdriver/remote/errorhandler.py", line 194, in check_response
    raise exception_class(message, screen, stacktrace)
selenium.common.exceptions.UnexpectedAlertPresentException: Alert Text: None
Message: unexpected alert open: {Alert text : There are unsaved changes}
  (Session info: chrome=61.0.3163.100)
  (Driver info: chromedriver=2.32.498537 (cb2f855cbc7b82e20387eaf9a43f6b99b6105061),platform=Mac OS X 10.12.5 x86_64)


During handling of the above exception, another exception occurred:

Traceback (most recent call last):
  File "/Users/lucianofeo/Desktop/golem/src/golem/browser.py", line 19, in _find_webelement
    webelement = root.find_element_by_id(selector_value)
  File "/Users/lucianofeo/Desktop/golem/env/lib/python3.6/site-packages/selenium-3.6.0-py3.6.egg/selenium/webdriver/remote/webdriver.py", line 341, in find_element_by_id
    return self.find_element(by=By.ID, value=id_)
  File "/Users/lucianofeo/Desktop/golem/env/lib/python3.6/site-packages/selenium-3.6.0-py3.6.egg/selenium/webdriver/remote/webdriver.py", line 843, in find_element
    'value': value})['value']
  File "/Users/lucianofeo/Desktop/golem/env/lib/python3.6/site-packages/selenium-3.6.0-py3.6.egg/selenium/webdriver/remote/webdriver.py", line 308, in execute
    self.error_handler.check_response(response)
  File "/Users/lucianofeo/Desktop/golem/env/lib/python3.6/site-packages/selenium-3.6.0-py3.6.egg/selenium/webdriver/remote/errorhandler.py", line 194, in check_response
    raise exception_class(message, screen, stacktrace)
selenium.common.exceptions.UnexpectedAlertPresentException: Alert Text: None
Message: unexpected alert open: {Alert text : There are unsaved changes}
  (Session info: chrome=61.0.3163.100)
  (Driver info: chromedriver=2.32.498537 (cb2f855cbc7b82e20387eaf9a43f6b99b6105061),platform=Mac OS X 10.12.5 x86_64)


During handling of the above exception, another exception occurred:

Traceback (most recent call last):
  File "/Users/lucianofeo/Desktop/golem/src/golem/browser.py", line 19, in _find_webelement
    webelement = root.find_element_by_id(selector_value)
  File "/Users/lucianofeo/Desktop/golem/env/lib/python3.6/site-packages/selenium-3.6.0-py3.6.egg/selenium/webdriver/remote/webdriver.py", line 341, in find_element_by_id
    return self.find_element(by=By.ID, value=id_)
  File "/Users/lucianofeo/Desktop/golem/env/lib/python3.6/site-packages/selenium-3.6.0-py3.6.egg/selenium/webdriver/remote/webdriver.py", line 843, in find_element
    'value': value})['value']
  File "/Users/lucianofeo/Desktop/golem/env/lib/python3.6/site-packages/selenium-3.6.0-py3.6.egg/selenium/webdriver/remote/webdriver.py", line 308, in execute
    self.error_handler.check_response(response)
  File "/Users/lucianofeo/Desktop/golem/env/lib/python3.6/site-packages/selenium-3.6.0-py3.6.egg/selenium/webdriver/remote/errorhandler.py", line 194, in check_response
    raise exception_class(message, screen, stacktrace)
selenium.common.exceptions.UnexpectedAlertPresentException: Alert Text: None
Message: unexpected alert open: {Alert text : There are unsaved changes}
  (Session info: chrome=61.0.3163.100)
  (Driver info: chromedriver=2.32.498537 (cb2f855cbc7b82e20387eaf9a43f6b99b6105061),platform=Mac OS X 10.12.5 x86_64)


During handling of the above exception, another exception occurred:

Traceback (most recent call last):
  File "/Users/lucianofeo/Desktop/golem/src/golem/browser.py", line 19, in _find_webelement
    webelement = root.find_element_by_id(selector_value)
  File "/Users/lucianofeo/Desktop/golem/env/lib/python3.6/site-packages/selenium-3.6.0-py3.6.egg/selenium/webdriver/remote/webdriver.py", line 341, in find_element_by_id
    return self.find_element(by=By.ID, value=id_)
  File "/Users/lucianofeo/Desktop/golem/env/lib/python3.6/site-packages/selenium-3.6.0-py3.6.egg/selenium/webdriver/remote/webdriver.py", line 843, in find_element
    'value': value})['value']
  File "/Users/lucianofeo/Desktop/golem/env/lib/python3.6/site-packages/selenium-3.6.0-py3.6.egg/selenium/webdriver/remote/webdriver.py", line 308, in execute
    self.error_handler.check_response(response)
  File "/Users/lucianofeo/Desktop/golem/env/lib/python3.6/site-packages/selenium-3.6.0-py3.6.egg/selenium/webdriver/remote/errorhandler.py", line 194, in check_response
    raise exception_class(message, screen, stacktrace)
selenium.common.exceptions.UnexpectedAlertPresentException: Alert Text: None
Message: unexpected alert open: {Alert text : There are unsaved changes}
  (Session info: chrome=61.0.3163.100)
  (Driver info: chromedriver=2.32.498537 (cb2f855cbc7b82e20387eaf9a43f6b99b6105061),platform=Mac OS X 10.12.5 x86_64)


During handling of the above exception, another exception occurred:

Traceback (most recent call last):
  File "/Users/lucianofeo/Desktop/golem/src/golem/browser.py", line 19, in _find_webelement
    webelement = root.find_element_by_id(selector_value)
  File "/Users/lucianofeo/Desktop/golem/env/lib/python3.6/site-packages/selenium-3.6.0-py3.6.egg/selenium/webdriver/remote/webdriver.py", line 341, in find_element_by_id
    return self.find_element(by=By.ID, value=id_)
  File "/Users/lucianofeo/Desktop/golem/env/lib/python3.6/site-packages/selenium-3.6.0-py3.6.egg/selenium/webdriver/remote/webdriver.py", line 843, in find_element
    'value': value})['value']
  File "/Users/lucianofeo/Desktop/golem/env/lib/python3.6/site-packages/selenium-3.6.0-py3.6.egg/selenium/webdriver/remote/webdriver.py", line 308, in execute
    self.error_handler.check_response(response)
  File "/Users/lucianofeo/Desktop/golem/env/lib/python3.6/site-packages/selenium-3.6.0-py3.6.egg/selenium/webdriver/remote/errorhandler.py", line 194, in check_response
    raise exception_class(message, screen, stacktrace)
selenium.common.exceptions.UnexpectedAlertPresentException: Alert Text: None
Message: unexpected alert open: {Alert text : There are unsaved changes}
  (Session info: chrome=61.0.3163.100)
  (Driver info: chromedriver=2.32.498537 (cb2f855cbc7b82e20387eaf9a43f6b99b6105061),platform=Mac OS X 10.12.5 x86_64)


During handling of the above exception, another exception occurred:

Traceback (most recent call last):
  File "/Users/lucianofeo/Desktop/golem/src/golem/browser.py", line 19, in _find_webelement
    webelement = root.find_element_by_id(selector_value)
  File "/Users/lucianofeo/Desktop/golem/env/lib/python3.6/site-packages/selenium-3.6.0-py3.6.egg/selenium/webdriver/remote/webdriver.py", line 341, in find_element_by_id
    return self.find_element(by=By.ID, value=id_)
  File "/Users/lucianofeo/Desktop/golem/env/lib/python3.6/site-packages/selenium-3.6.0-py3.6.egg/selenium/webdriver/remote/webdriver.py", line 843, in find_element
    'value': value})['value']
  File "/Users/lucianofeo/Desktop/golem/env/lib/python3.6/site-packages/selenium-3.6.0-py3.6.egg/selenium/webdriver/remote/webdriver.py", line 308, in execute
    self.error_handler.check_response(response)
  File "/Users/lucianofeo/Desktop/golem/env/lib/python3.6/site-packages/selenium-3.6.0-py3.6.egg/selenium/webdriver/remote/errorhandler.py", line 194, in check_response
    raise exception_class(message, screen, stacktrace)
selenium.common.exceptions.UnexpectedAlertPresentException: Alert Text: None
Message: unexpected alert open: {Alert text : There are unsaved changes}
  (Session info: chrome=61.0.3163.100)
  (Driver info: chromedriver=2.32.498537 (cb2f855cbc7b82e20387eaf9a43f6b99b6105061),platform=Mac OS X 10.12.5 x86_64)


During handling of the above exception, another exception occurred:

Traceback (most recent call last):
  File "/Users/lucianofeo/Desktop/golem/src/golem/browser.py", line 19, in _find_webelement
    webelement = root.find_element_by_id(selector_value)
  File "/Users/lucianofeo/Desktop/golem/env/lib/python3.6/site-packages/selenium-3.6.0-py3.6.egg/selenium/webdriver/remote/webdriver.py", line 341, in find_element_by_id
    return self.find_element(by=By.ID, value=id_)
  File "/Users/lucianofeo/Desktop/golem/env/lib/python3.6/site-packages/selenium-3.6.0-py3.6.egg/selenium/webdriver/remote/webdriver.py", line 843, in find_element
    'value': value})['value']
  File "/Users/lucianofeo/Desktop/golem/env/lib/python3.6/site-packages/selenium-3.6.0-py3.6.egg/selenium/webdriver/remote/webdriver.py", line 308, in execute
    self.error_handler.check_response(response)
  File "/Users/lucianofeo/Desktop/golem/env/lib/python3.6/site-packages/selenium-3.6.0-py3.6.egg/selenium/webdriver/remote/errorhandler.py", line 194, in check_response
    raise exception_class(message, screen, stacktrace)
selenium.common.exceptions.UnexpectedAlertPresentException: Alert Text: None
Message: unexpected alert open: {Alert text : There are unsaved changes}
  (Session info: chrome=61.0.3163.100)
  (Driver info: chromedriver=2.32.498537 (cb2f855cbc7b82e20387eaf9a43f6b99b6105061),platform=Mac OS X 10.12.5 x86_64)


During handling of the above exception, another exception occurred:

Traceback (most recent call last):
  File "/Users/lucianofeo/Desktop/golem/src/golem/browser.py", line 19, in _find_webelement
    webelement = root.find_element_by_id(selector_value)
  File "/Users/lucianofeo/Desktop/golem/env/lib/python3.6/site-packages/selenium-3.6.0-py3.6.egg/selenium/webdriver/remote/webdriver.py", line 341, in find_element_by_id
    return self.find_element(by=By.ID, value=id_)
  File "/Users/lucianofeo/Desktop/golem/env/lib/python3.6/site-packages/selenium-3.6.0-py3.6.egg/selenium/webdriver/remote/webdriver.py", line 843, in find_element
    'value': value})['value']
  File "/Users/lucianofeo/Desktop/golem/env/lib/python3.6/site-packages/selenium-3.6.0-py3.6.egg/selenium/webdriver/remote/webdriver.py", line 308, in execute
    self.error_handler.check_response(response)
  File "/Users/lucianofeo/Desktop/golem/env/lib/python3.6/site-packages/selenium-3.6.0-py3.6.egg/selenium/webdriver/remote/errorhandler.py", line 194, in check_response
    raise exception_class(message, screen, stacktrace)
selenium.common.exceptions.UnexpectedAlertPresentException: Alert Text: None
Message: unexpected alert open: {Alert text : There are unsaved changes}
  (Session info: chrome=61.0.3163.100)
  (Driver info: chromedriver=2.32.498537 (cb2f855cbc7b82e20387eaf9a43f6b99b6105061),platform=Mac OS X 10.12.5 x86_64)


During handling of the above exception, another exception occurred:

Traceback (most recent call last):
  File "/Users/lucianofeo/Desktop/golem/src/golem/browser.py", line 19, in _find_webelement
    webelement = root.find_element_by_id(selector_value)
  File "/Users/lucianofeo/Desktop/golem/env/lib/python3.6/site-packages/selenium-3.6.0-py3.6.egg/selenium/webdriver/remote/webdriver.py", line 341, in find_element_by_id
    return self.find_element(by=By.ID, value=id_)
  File "/Users/lucianofeo/Desktop/golem/env/lib/python3.6/site-packages/selenium-3.6.0-py3.6.egg/selenium/webdriver/remote/webdriver.py", line 843, in find_element
    'value': value})['value']
  File "/Users/lucianofeo/Desktop/golem/env/lib/python3.6/site-packages/selenium-3.6.0-py3.6.egg/selenium/webdriver/remote/webdriver.py", line 308, in execute
    self.error_handler.check_response(response)
  File "/Users/lucianofeo/Desktop/golem/env/lib/python3.6/site-packages/selenium-3.6.0-py3.6.egg/selenium/webdriver/remote/errorhandler.py", line 194, in check_response
    raise exception_class(message, screen, stacktrace)
selenium.common.exceptions.UnexpectedAlertPresentException: Alert Text: None
Message: unexpected alert open: {Alert text : There are unsaved changes}
  (Session info: chrome=61.0.3163.100)
  (Driver info: chromedriver=2.32.498537 (cb2f855cbc7b82e20387eaf9a43f6b99b6105061),platform=Mac OS X 10.12.5 x86_64)


During handling of the above exception, another exception occurred:

Traceback (most recent call last):
  File "/Users/lucianofeo/Desktop/golem/src/golem/browser.py", line 19, in _find_webelement
    webelement = root.find_element_by_id(selector_value)
  File "/Users/lucianofeo/Desktop/golem/env/lib/python3.6/site-packages/selenium-3.6.0-py3.6.egg/selenium/webdriver/remote/webdriver.py", line 341, in find_element_by_id
    return self.find_element(by=By.ID, value=id_)
  File "/Users/lucianofeo/Desktop/golem/env/lib/python3.6/site-packages/selenium-3.6.0-py3.6.egg/selenium/webdriver/remote/webdriver.py", line 843, in find_element
    'value': value})['value']
  File "/Users/lucianofeo/Desktop/golem/env/lib/python3.6/site-packages/selenium-3.6.0-py3.6.egg/selenium/webdriver/remote/webdriver.py", line 308, in execute
    self.error_handler.check_response(response)
  File "/Users/lucianofeo/Desktop/golem/env/lib/python3.6/site-packages/selenium-3.6.0-py3.6.egg/selenium/webdriver/remote/errorhandler.py", line 194, in check_response
    raise exception_class(message, screen, stacktrace)
selenium.common.exceptions.UnexpectedAlertPresentException: Alert Text: None
Message: unexpected alert open: {Alert text : There are unsaved changes}
  (Session info: chrome=61.0.3163.100)
  (Driver info: chromedriver=2.32.498537 (cb2f855cbc7b82e20387eaf9a43f6b99b6105061),platform=Mac OS X 10.12.5 x86_64)


During handling of the above exception, another exception occurred:

Traceback (most recent call last):
  File "/Users/lucianofeo/Desktop/golem/src/golem/browser.py", line 19, in _find_webelement
    webelement = root.find_element_by_id(selector_value)
  File "/Users/lucianofeo/Desktop/golem/env/lib/python3.6/site-packages/selenium-3.6.0-py3.6.egg/selenium/webdriver/remote/webdriver.py", line 341, in find_element_by_id
    return self.find_element(by=By.ID, value=id_)
  File "/Users/lucianofeo/Desktop/golem/env/lib/python3.6/site-packages/selenium-3.6.0-py3.6.egg/selenium/webdriver/remote/webdriver.py", line 843, in find_element
    'value': value})['value']
  File "/Users/lucianofeo/Desktop/golem/env/lib/python3.6/site-packages/selenium-3.6.0-py3.6.egg/selenium/webdriver/remote/webdriver.py", line 308, in execute
    self.error_handler.check_response(response)
  File "/Users/lucianofeo/Desktop/golem/env/lib/python3.6/site-packages/selenium-3.6.0-py3.6.egg/selenium/webdriver/remote/errorhandler.py", line 194, in check_response
    raise exception_class(message, screen, stacktrace)
selenium.common.exceptions.UnexpectedAlertPresentException: Alert Text: None
Message: unexpected alert open: {Alert text : There are unsaved changes}
  (Session info: chrome=61.0.3163.100)
  (Driver info: chromedriver=2.32.498537 (cb2f855cbc7b82e20387eaf9a43f6b99b6105061),platform=Mac OS X 10.12.5 x86_64)


During handling of the above exception, another exception occurred:

Traceback (most recent call last):
  File "/Users/lucianofeo/Desktop/golem/src/golem/browser.py", line 19, in _find_webelement
    webelement = root.find_element_by_id(selector_value)
  File "/Users/lucianofeo/Desktop/golem/env/lib/python3.6/site-packages/selenium-3.6.0-py3.6.egg/selenium/webdriver/remote/webdriver.py", line 341, in find_element_by_id
    return self.find_element(by=By.ID, value=id_)
  File "/Users/lucianofeo/Desktop/golem/env/lib/python3.6/site-packages/selenium-3.6.0-py3.6.egg/selenium/webdriver/remote/webdriver.py", line 843, in find_element
    'value': value})['value']
  File "/Users/lucianofeo/Desktop/golem/env/lib/python3.6/site-packages/selenium-3.6.0-py3.6.egg/selenium/webdriver/remote/webdriver.py", line 308, in execute
    self.error_handler.check_response(response)
  File "/Users/lucianofeo/Desktop/golem/env/lib/python3.6/site-packages/selenium-3.6.0-py3.6.egg/selenium/webdriver/remote/errorhandler.py", line 194, in check_response
    raise exception_class(message, screen, stacktrace)
selenium.common.exceptions.UnexpectedAlertPresentException: Alert Text: None
Message: unexpected alert open: {Alert text : There are unsaved changes}
  (Session info: chrome=61.0.3163.100)
  (Driver info: chromedriver=2.32.498537 (cb2f855cbc7b82e20387eaf9a43f6b99b6105061),platform=Mac OS X 10.12.5 x86_64)


During handling of the above exception, another exception occurred:

Traceback (most recent call last):
  File "/Users/lucianofeo/Desktop/golem/src/golem/browser.py", line 19, in _find_webelement
    webelement = root.find_element_by_id(selector_value)
  File "/Users/lucianofeo/Desktop/golem/env/lib/python3.6/site-packages/selenium-3.6.0-py3.6.egg/selenium/webdriver/remote/webdriver.py", line 341, in find_element_by_id
    return self.find_element(by=By.ID, value=id_)
  File "/Users/lucianofeo/Desktop/golem/env/lib/python3.6/site-packages/selenium-3.6.0-py3.6.egg/selenium/webdriver/remote/webdriver.py", line 843, in find_element
    'value': value})['value']
  File "/Users/lucianofeo/Desktop/golem/env/lib/python3.6/site-packages/selenium-3.6.0-py3.6.egg/selenium/webdriver/remote/webdriver.py", line 308, in execute
    self.error_handler.check_response(response)
  File "/Users/lucianofeo/Desktop/golem/env/lib/python3.6/site-packages/selenium-3.6.0-py3.6.egg/selenium/webdriver/remote/errorhandler.py", line 194, in check_response
    raise exception_class(message, screen, stacktrace)
selenium.common.exceptions.UnexpectedAlertPresentException: Alert Text: None
Message: unexpected alert open: {Alert text : There are unsaved changes}
  (Session info: chrome=61.0.3163.100)
  (Driver info: chromedriver=2.32.498537 (cb2f855cbc7b82e20387eaf9a43f6b99b6105061),platform=Mac OS X 10.12.5 x86_64)


During handling of the above exception, another exception occurred:

Traceback (most recent call last):
  File "/Users/lucianofeo/Desktop/golem/src/golem/browser.py", line 19, in _find_webelement
    webelement = root.find_element_by_id(selector_value)
  File "/Users/lucianofeo/Desktop/golem/env/lib/python3.6/site-packages/selenium-3.6.0-py3.6.egg/selenium/webdriver/remote/webdriver.py", line 341, in find_element_by_id
    return self.find_element(by=By.ID, value=id_)
  File "/Users/lucianofeo/Desktop/golem/env/lib/python3.6/site-packages/selenium-3.6.0-py3.6.egg/selenium/webdriver/remote/webdriver.py", line 843, in find_element
    'value': value})['value']
  File "/Users/lucianofeo/Desktop/golem/env/lib/python3.6/site-packages/selenium-3.6.0-py3.6.egg/selenium/webdriver/remote/webdriver.py", line 308, in execute
    self.error_handler.check_response(response)
  File "/Users/lucianofeo/Desktop/golem/env/lib/python3.6/site-packages/selenium-3.6.0-py3.6.egg/selenium/webdriver/remote/errorhandler.py", line 194, in check_response
    raise exception_class(message, screen, stacktrace)
selenium.common.exceptions.UnexpectedAlertPresentException: Alert Text: None
Message: unexpected alert open: {Alert text : There are unsaved changes}
  (Session info: chrome=61.0.3163.100)
  (Driver info: chromedriver=2.32.498537 (cb2f855cbc7b82e20387eaf9a43f6b99b6105061),platform=Mac OS X 10.12.5 x86_64)


During handling of the above exception, another exception occurred:

Traceback (most recent call last):
  File "/Users/lucianofeo/Desktop/golem/src/golem/browser.py", line 19, in _find_webelement
    webelement = root.find_element_by_id(selector_value)
  File "/Users/lucianofeo/Desktop/golem/env/lib/python3.6/site-packages/selenium-3.6.0-py3.6.egg/selenium/webdriver/remote/webdriver.py", line 341, in find_element_by_id
    return self.find_element(by=By.ID, value=id_)
  File "/Users/lucianofeo/Desktop/golem/env/lib/python3.6/site-packages/selenium-3.6.0-py3.6.egg/selenium/webdriver/remote/webdriver.py", line 843, in find_element
    'value': value})['value']
  File "/Users/lucianofeo/Desktop/golem/env/lib/python3.6/site-packages/selenium-3.6.0-py3.6.egg/selenium/webdriver/remote/webdriver.py", line 308, in execute
    self.error_handler.check_response(response)
  File "/Users/lucianofeo/Desktop/golem/env/lib/python3.6/site-packages/selenium-3.6.0-py3.6.egg/selenium/webdriver/remote/errorhandler.py", line 194, in check_response
    raise exception_class(message, screen, stacktrace)
selenium.common.exceptions.UnexpectedAlertPresentException: Alert Text: None
Message: unexpected alert open: {Alert text : There are unsaved changes}
  (Session info: chrome=61.0.3163.100)
  (Driver info: chromedriver=2.32.498537 (cb2f855cbc7b82e20387eaf9a43f6b99b6105061),platform=Mac OS X 10.12.5 x86_64)


During handling of the above exception, another exception occurred:

Traceback (most recent call last):
  File "/Users/lucianofeo/Desktop/golem/src/golem/browser.py", line 19, in _find_webelement
    webelement = root.find_element_by_id(selector_value)
  File "/Users/lucianofeo/Desktop/golem/env/lib/python3.6/site-packages/selenium-3.6.0-py3.6.egg/selenium/webdriver/remote/webdriver.py", line 341, in find_element_by_id
    return self.find_element(by=By.ID, value=id_)
  File "/Users/lucianofeo/Desktop/golem/env/lib/python3.6/site-packages/selenium-3.6.0-py3.6.egg/selenium/webdriver/remote/webdriver.py", line 843, in find_element
    'value': value})['value']
  File "/Users/lucianofeo/Desktop/golem/env/lib/python3.6/site-packages/selenium-3.6.0-py3.6.egg/selenium/webdriver/remote/webdriver.py", line 308, in execute
    self.error_handler.check_response(response)
  File "/Users/lucianofeo/Desktop/golem/env/lib/python3.6/site-packages/selenium-3.6.0-py3.6.egg/selenium/webdriver/remote/errorhandler.py", line 194, in check_response
    raise exception_class(message, screen, stacktrace)
selenium.common.exceptions.UnexpectedAlertPresentException: Alert Text: None
Message: unexpected alert open: {Alert text : There are unsaved changes}
  (Session info: chrome=61.0.3163.100)
  (Driver info: chromedriver=2.32.498537 (cb2f855cbc7b82e20387eaf9a43f6b99b6105061),platform=Mac OS X 10.12.5 x86_64)


During handling of the above exception, another exception occurred:

Traceback (most recent call last):
  File "/Users/lucianofeo/Desktop/golem/src/golem/browser.py", line 19, in _find_webelement
    webelement = root.find_element_by_id(selector_value)
  File "/Users/lucianofeo/Desktop/golem/env/lib/python3.6/site-packages/selenium-3.6.0-py3.6.egg/selenium/webdriver/remote/webdriver.py", line 341, in find_element_by_id
    return self.find_element(by=By.ID, value=id_)
  File "/Users/lucianofeo/Desktop/golem/env/lib/python3.6/site-packages/selenium-3.6.0-py3.6.egg/selenium/webdriver/remote/webdriver.py", line 843, in find_element
    'value': value})['value']
  File "/Users/lucianofeo/Desktop/golem/env/lib/python3.6/site-packages/selenium-3.6.0-py3.6.egg/selenium/webdriver/remote/webdriver.py", line 308, in execute
    self.error_handler.check_response(response)
  File "/Users/lucianofeo/Desktop/golem/env/lib/python3.6/site-packages/selenium-3.6.0-py3.6.egg/selenium/webdriver/remote/errorhandler.py", line 194, in check_response
    raise exception_class(message, screen, stacktrace)
selenium.common.exceptions.UnexpectedAlertPresentException: Alert Text: None
Message: unexpected alert open: {Alert text : There are unsaved changes}
  (Session info: chrome=61.0.3163.100)
  (Driver info: chromedriver=2.32.498537 (cb2f855cbc7b82e20387eaf9a43f6b99b6105061),platform=Mac OS X 10.12.5 x86_64)


During handling of the above exception, another exception occurred:

Traceback (most recent call last):
  File "/Users/lucianofeo/Desktop/golem/src/golem/browser.py", line 19, in _find_webelement
    webelement = root.find_element_by_id(selector_value)
  File "/Users/lucianofeo/Desktop/golem/env/lib/python3.6/site-packages/selenium-3.6.0-py3.6.egg/selenium/webdriver/remote/webdriver.py", line 341, in find_element_by_id
    return self.find_element(by=By.ID, value=id_)
  File "/Users/lucianofeo/Desktop/golem/env/lib/python3.6/site-packages/selenium-3.6.0-py3.6.egg/selenium/webdriver/remote/webdriver.py", line 843, in find_element
    'value': value})['value']
  File "/Users/lucianofeo/Desktop/golem/env/lib/python3.6/site-packages/selenium-3.6.0-py3.6.egg/selenium/webdriver/remote/webdriver.py", line 308, in execute
    self.error_handler.check_response(response)
  File "/Users/lucianofeo/Desktop/golem/env/lib/python3.6/site-packages/selenium-3.6.0-py3.6.egg/selenium/webdriver/remote/errorhandler.py", line 194, in check_response
    raise exception_class(message, screen, stacktrace)
selenium.common.exceptions.UnexpectedAlertPresentException: Alert Text: None
Message: unexpected alert open: {Alert text : There are unsaved changes}
  (Session info: chrome=61.0.3163.100)
  (Driver info: chromedriver=2.32.498537 (cb2f855cbc7b82e20387eaf9a43f6b99b6105061),platform=Mac OS X 10.12.5 x86_64)


During handling of the above exception, another exception occurred:

Traceback (most recent call last):
  File "/Users/lucianofeo/Desktop/golem/src/golem/browser.py", line 19, in _find_webelement
    webelement = root.find_element_by_id(selector_value)
  File "/Users/lucianofeo/Desktop/golem/env/lib/python3.6/site-packages/selenium-3.6.0-py3.6.egg/selenium/webdriver/remote/webdriver.py", line 341, in find_element_by_id
    return self.find_element(by=By.ID, value=id_)
  File "/Users/lucianofeo/Desktop/golem/env/lib/python3.6/site-packages/selenium-3.6.0-py3.6.egg/selenium/webdriver/remote/webdriver.py", line 843, in find_element
    'value': value})['value']
  File "/Users/lucianofeo/Desktop/golem/env/lib/python3.6/site-packages/selenium-3.6.0-py3.6.egg/selenium/webdriver/remote/webdriver.py", line 308, in execute
    self.error_handler.check_response(response)
  File "/Users/lucianofeo/Desktop/golem/env/lib/python3.6/site-packages/selenium-3.6.0-py3.6.egg/selenium/webdriver/remote/errorhandler.py", line 194, in check_response
    raise exception_class(message, screen, stacktrace)
selenium.common.exceptions.UnexpectedAlertPresentException: Alert Text: None
Message: unexpected alert open: {Alert text : There are unsaved changes}
  (Session info: chrome=61.0.3163.100)
  (Driver info: chromedriver=2.32.498537 (cb2f855cbc7b82e20387eaf9a43f6b99b6105061),platform=Mac OS X 10.12.5 x86_64)


During handling of the above exception, another exception occurred:

Traceback (most recent call last):
  File "/Users/lucianofeo/Desktop/golem/src/golem/browser.py", line 19, in _find_webelement
    webelement = root.find_element_by_id(selector_value)
  File "/Users/lucianofeo/Desktop/golem/env/lib/python3.6/site-packages/selenium-3.6.0-py3.6.egg/selenium/webdriver/remote/webdriver.py", line 341, in find_element_by_id
    return self.find_element(by=By.ID, value=id_)
  File "/Users/lucianofeo/Desktop/golem/env/lib/python3.6/site-packages/selenium-3.6.0-py3.6.egg/selenium/webdriver/remote/webdriver.py", line 843, in find_element
    'value': value})['value']
  File "/Users/lucianofeo/Desktop/golem/env/lib/python3.6/site-packages/selenium-3.6.0-py3.6.egg/selenium/webdriver/remote/webdriver.py", line 308, in execute
    self.error_handler.check_response(response)
  File "/Users/lucianofeo/Desktop/golem/env/lib/python3.6/site-packages/selenium-3.6.0-py3.6.egg/selenium/webdriver/remote/errorhandler.py", line 194, in check_response
    raise exception_class(message, screen, stacktrace)
selenium.common.exceptions.UnexpectedAlertPresentException: Alert Text: None
Message: unexpected alert open: {Alert text : There are unsaved changes}
  (Session info: chrome=61.0.3163.100)
  (Driver info: chromedriver=2.32.498537 (cb2f855cbc7b82e20387eaf9a43f6b99b6105061),platform=Mac OS X 10.12.5 x86_64)


During handling of the above exception, another exception occurred:

Traceback (most recent call last):
  File "/Users/lucianofeo/Desktop/golem/src/golem/browser.py", line 19, in _find_webelement
    webelement = root.find_element_by_id(selector_value)
  File "/Users/lucianofeo/Desktop/golem/env/lib/python3.6/site-packages/selenium-3.6.0-py3.6.egg/selenium/webdriver/remote/webdriver.py", line 341, in find_element_by_id
    return self.find_element(by=By.ID, value=id_)
  File "/Users/lucianofeo/Desktop/golem/env/lib/python3.6/site-packages/selenium-3.6.0-py3.6.egg/selenium/webdriver/remote/webdriver.py", line 843, in find_element
    'value': value})['value']
  File "/Users/lucianofeo/Desktop/golem/env/lib/python3.6/site-packages/selenium-3.6.0-py3.6.egg/selenium/webdriver/remote/webdriver.py", line 308, in execute
    self.error_handler.check_response(response)
  File "/Users/lucianofeo/Desktop/golem/env/lib/python3.6/site-packages/selenium-3.6.0-py3.6.egg/selenium/webdriver/remote/errorhandler.py", line 194, in check_response
    raise exception_class(message, screen, stacktrace)
selenium.common.exceptions.UnexpectedAlertPresentException: Alert Text: None
Message: unexpected alert open: {Alert text : There are unsaved changes}
  (Session info: chrome=61.0.3163.100)
  (Driver info: chromedriver=2.32.498537 (cb2f855cbc7b82e20387eaf9a43f6b99b6105061),platform=Mac OS X 10.12.5 x86_64)


During handling of the above exception, another exception occurred:

Traceback (most recent call last):
  File "/Users/lucianofeo/Desktop/golem/src/golem/browser.py", line 19, in _find_webelement
    webelement = root.find_element_by_id(selector_value)
  File "/Users/lucianofeo/Desktop/golem/env/lib/python3.6/site-packages/selenium-3.6.0-py3.6.egg/selenium/webdriver/remote/webdriver.py", line 341, in find_element_by_id
    return self.find_element(by=By.ID, value=id_)
  File "/Users/lucianofeo/Desktop/golem/env/lib/python3.6/site-packages/selenium-3.6.0-py3.6.egg/selenium/webdriver/remote/webdriver.py", line 843, in find_element
    'value': value})['value']
  File "/Users/lucianofeo/Desktop/golem/env/lib/python3.6/site-packages/selenium-3.6.0-py3.6.egg/selenium/webdriver/remote/webdriver.py", line 308, in execute
    self.error_handler.check_response(response)
  File "/Users/lucianofeo/Desktop/golem/env/lib/python3.6/site-packages/selenium-3.6.0-py3.6.egg/selenium/webdriver/remote/errorhandler.py", line 194, in check_response
    raise exception_class(message, screen, stacktrace)
selenium.common.exceptions.UnexpectedAlertPresentException: Alert Text: None
Message: unexpected alert open: {Alert text : There are unsaved changes}
  (Session info: chrome=61.0.3163.100)
  (Driver info: chromedriver=2.32.498537 (cb2f855cbc7b82e20387eaf9a43f6b99b6105061),platform=Mac OS X 10.12.5 x86_64)


During handling of the above exception, another exception occurred:

Traceback (most recent call last):
  File "/Users/lucianofeo/Desktop/golem/src/golem/browser.py", line 19, in _find_webelement
    webelement = root.find_element_by_id(selector_value)
  File "/Users/lucianofeo/Desktop/golem/env/lib/python3.6/site-packages/selenium-3.6.0-py3.6.egg/selenium/webdriver/remote/webdriver.py", line 341, in find_element_by_id
    return self.find_element(by=By.ID, value=id_)
  File "/Users/lucianofeo/Desktop/golem/env/lib/python3.6/site-packages/selenium-3.6.0-py3.6.egg/selenium/webdriver/remote/webdriver.py", line 843, in find_element
    'value': value})['value']
  File "/Users/lucianofeo/Desktop/golem/env/lib/python3.6/site-packages/selenium-3.6.0-py3.6.egg/selenium/webdriver/remote/webdriver.py", line 308, in execute
    self.error_handler.check_response(response)
  File "/Users/lucianofeo/Desktop/golem/env/lib/python3.6/site-packages/selenium-3.6.0-py3.6.egg/selenium/webdriver/remote/errorhandler.py", line 194, in check_response
    raise exception_class(message, screen, stacktrace)
selenium.common.exceptions.UnexpectedAlertPresentException: Alert Text: None
Message: unexpected alert open: {Alert text : There are unsaved changes}
  (Session info: chrome=61.0.3163.100)
  (Driver info: chromedriver=2.32.498537 (cb2f855cbc7b82e20387eaf9a43f6b99b6105061),platform=Mac OS X 10.12.5 x86_64)


During handling of the above exception, another exception occurred:

Traceback (most recent call last):
  File "/Users/lucianofeo/Desktop/golem/src/golem/browser.py", line 19, in _find_webelement
    webelement = root.find_element_by_id(selector_value)
  File "/Users/lucianofeo/Desktop/golem/env/lib/python3.6/site-packages/selenium-3.6.0-py3.6.egg/selenium/webdriver/remote/webdriver.py", line 341, in find_element_by_id
    return self.find_element(by=By.ID, value=id_)
  File "/Users/lucianofeo/Desktop/golem/env/lib/python3.6/site-packages/selenium-3.6.0-py3.6.egg/selenium/webdriver/remote/webdriver.py", line 843, in find_element
    'value': value})['value']
  File "/Users/lucianofeo/Desktop/golem/env/lib/python3.6/site-packages/selenium-3.6.0-py3.6.egg/selenium/webdriver/remote/webdriver.py", line 308, in execute
    self.error_handler.check_response(response)
  File "/Users/lucianofeo/Desktop/golem/env/lib/python3.6/site-packages/selenium-3.6.0-py3.6.egg/selenium/webdriver/remote/errorhandler.py", line 194, in check_response
    raise exception_class(message, screen, stacktrace)
selenium.common.exceptions.UnexpectedAlertPresentException: Alert Text: None
Message: unexpected alert open: {Alert text : There are unsaved changes}
  (Session info: chrome=61.0.3163.100)
  (Driver info: chromedriver=2.32.498537 (cb2f855cbc7b82e20387eaf9a43f6b99b6105061),platform=Mac OS X 10.12.5 x86_64)


During handling of the above exception, another exception occurred:

Traceback (most recent call last):
  File "/Users/lucianofeo/Desktop/golem/src/golem/browser.py", line 19, in _find_webelement
    webelement = root.find_element_by_id(selector_value)
  File "/Users/lucianofeo/Desktop/golem/env/lib/python3.6/site-packages/selenium-3.6.0-py3.6.egg/selenium/webdriver/remote/webdriver.py", line 341, in find_element_by_id
    return self.find_element(by=By.ID, value=id_)
  File "/Users/lucianofeo/Desktop/golem/env/lib/python3.6/site-packages/selenium-3.6.0-py3.6.egg/selenium/webdriver/remote/webdriver.py", line 843, in find_element
    'value': value})['value']
  File "/Users/lucianofeo/Desktop/golem/env/lib/python3.6/site-packages/selenium-3.6.0-py3.6.egg/selenium/webdriver/remote/webdriver.py", line 308, in execute
    self.error_handler.check_response(response)
  File "/Users/lucianofeo/Desktop/golem/env/lib/python3.6/site-packages/selenium-3.6.0-py3.6.egg/selenium/webdriver/remote/errorhandler.py", line 194, in check_response
    raise exception_class(message, screen, stacktrace)
selenium.common.exceptions.UnexpectedAlertPresentException: Alert Text: None
Message: unexpected alert open: {Alert text : There are unsaved changes}
  (Session info: chrome=61.0.3163.100)
  (Driver info: chromedriver=2.32.498537 (cb2f855cbc7b82e20387eaf9a43f6b99b6105061),platform=Mac OS X 10.12.5 x86_64)


During handling of the above exception, another exception occurred:

Traceback (most recent call last):
  File "/Users/lucianofeo/Desktop/golem/src/golem/browser.py", line 19, in _find_webelement
    webelement = root.find_element_by_id(selector_value)
  File "/Users/lucianofeo/Desktop/golem/env/lib/python3.6/site-packages/selenium-3.6.0-py3.6.egg/selenium/webdriver/remote/webdriver.py", line 341, in find_element_by_id
    return self.find_element(by=By.ID, value=id_)
  File "/Users/lucianofeo/Desktop/golem/env/lib/python3.6/site-packages/selenium-3.6.0-py3.6.egg/selenium/webdriver/remote/webdriver.py", line 843, in find_element
    'value': value})['value']
  File "/Users/lucianofeo/Desktop/golem/env/lib/python3.6/site-packages/selenium-3.6.0-py3.6.egg/selenium/webdriver/remote/webdriver.py", line 308, in execute
    self.error_handler.check_response(response)
  File "/Users/lucianofeo/Desktop/golem/env/lib/python3.6/site-packages/selenium-3.6.0-py3.6.egg/selenium/webdriver/remote/errorhandler.py", line 194, in check_response
    raise exception_class(message, screen, stacktrace)
selenium.common.exceptions.UnexpectedAlertPresentException: Alert Text: None
Message: unexpected alert open: {Alert text : There are unsaved changes}
  (Session info: chrome=61.0.3163.100)
  (Driver info: chromedriver=2.32.498537 (cb2f855cbc7b82e20387eaf9a43f6b99b6105061),platform=Mac OS X 10.12.5 x86_64)


During handling of the above exception, another exception occurred:

Traceback (most recent call last):
  File "/Users/lucianofeo/Desktop/golem/src/golem/browser.py", line 19, in _find_webelement
    webelement = root.find_element_by_id(selector_value)
  File "/Users/lucianofeo/Desktop/golem/env/lib/python3.6/site-packages/selenium-3.6.0-py3.6.egg/selenium/webdriver/remote/webdriver.py", line 341, in find_element_by_id
    return self.find_element(by=By.ID, value=id_)
  File "/Users/lucianofeo/Desktop/golem/env/lib/python3.6/site-packages/selenium-3.6.0-py3.6.egg/selenium/webdriver/remote/webdriver.py", line 843, in find_element
    'value': value})['value']
  File "/Users/lucianofeo/Desktop/golem/env/lib/python3.6/site-packages/selenium-3.6.0-py3.6.egg/selenium/webdriver/remote/webdriver.py", line 308, in execute
    self.error_handler.check_response(response)
  File "/Users/lucianofeo/Desktop/golem/env/lib/python3.6/site-packages/selenium-3.6.0-py3.6.egg/selenium/webdriver/remote/errorhandler.py", line 194, in check_response
    raise exception_class(message, screen, stacktrace)
selenium.common.exceptions.UnexpectedAlertPresentException: Alert Text: None
Message: unexpected alert open: {Alert text : There are unsaved changes}
  (Session info: chrome=61.0.3163.100)
  (Driver info: chromedriver=2.32.498537 (cb2f855cbc7b82e20387eaf9a43f6b99b6105061),platform=Mac OS X 10.12.5 x86_64)


During handling of the above exception, another exception occurred:

Traceback (most recent call last):
  File "/Users/lucianofeo/Desktop/golem/src/golem/browser.py", line 19, in _find_webelement
    webelement = root.find_element_by_id(selector_value)
  File "/Users/lucianofeo/Desktop/golem/env/lib/python3.6/site-packages/selenium-3.6.0-py3.6.egg/selenium/webdriver/remote/webdriver.py", line 341, in find_element_by_id
    return self.find_element(by=By.ID, value=id_)
  File "/Users/lucianofeo/Desktop/golem/env/lib/python3.6/site-packages/selenium-3.6.0-py3.6.egg/selenium/webdriver/remote/webdriver.py", line 843, in find_element
    'value': value})['value']
  File "/Users/lucianofeo/Desktop/golem/env/lib/python3.6/site-packages/selenium-3.6.0-py3.6.egg/selenium/webdriver/remote/webdriver.py", line 308, in execute
    self.error_handler.check_response(response)
  File "/Users/lucianofeo/Desktop/golem/env/lib/python3.6/site-packages/selenium-3.6.0-py3.6.egg/selenium/webdriver/remote/errorhandler.py", line 194, in check_response
    raise exception_class(message, screen, stacktrace)
selenium.common.exceptions.UnexpectedAlertPresentException: Alert Text: None
Message: unexpected alert open: {Alert text : There are unsaved changes}
  (Session info: chrome=61.0.3163.100)
  (Driver info: chromedriver=2.32.498537 (cb2f855cbc7b82e20387eaf9a43f6b99b6105061),platform=Mac OS X 10.12.5 x86_64)


During handling of the above exception, another exception occurred:

Traceback (most recent call last):
  File "/Users/lucianofeo/Desktop/golem/src/golem/browser.py", line 19, in _find_webelement
    webelement = root.find_element_by_id(selector_value)
  File "/Users/lucianofeo/Desktop/golem/env/lib/python3.6/site-packages/selenium-3.6.0-py3.6.egg/selenium/webdriver/remote/webdriver.py", line 341, in find_element_by_id
    return self.find_element(by=By.ID, value=id_)
  File "/Users/lucianofeo/Desktop/golem/env/lib/python3.6/site-packages/selenium-3.6.0-py3.6.egg/selenium/webdriver/remote/webdriver.py", line 843, in find_element
    'value': value})['value']
  File "/Users/lucianofeo/Desktop/golem/env/lib/python3.6/site-packages/selenium-3.6.0-py3.6.egg/selenium/webdriver/remote/webdriver.py", line 308, in execute
    self.error_handler.check_response(response)
  File "/Users/lucianofeo/Desktop/golem/env/lib/python3.6/site-packages/selenium-3.6.0-py3.6.egg/selenium/webdriver/remote/errorhandler.py", line 194, in check_response
    raise exception_class(message, screen, stacktrace)
selenium.common.exceptions.UnexpectedAlertPresentException: Alert Text: None
Message: unexpected alert open: {Alert text : There are unsaved changes}
  (Session info: chrome=61.0.3163.100)
  (Driver info: chromedriver=2.32.498537 (cb2f855cbc7b82e20387eaf9a43f6b99b6105061),platform=Mac OS X 10.12.5 x86_64)


During handling of the above exception, another exception occurred:

Traceback (most recent call last):
  File "/Users/lucianofeo/Desktop/golem/src/golem/browser.py", line 19, in _find_webelement
    webelement = root.find_element_by_id(selector_value)
  File "/Users/lucianofeo/Desktop/golem/env/lib/python3.6/site-packages/selenium-3.6.0-py3.6.egg/selenium/webdriver/remote/webdriver.py", line 341, in find_element_by_id
    return self.find_element(by=By.ID, value=id_)
  File "/Users/lucianofeo/Desktop/golem/env/lib/python3.6/site-packages/selenium-3.6.0-py3.6.egg/selenium/webdriver/remote/webdriver.py", line 843, in find_element
    'value': value})['value']
  File "/Users/lucianofeo/Desktop/golem/env/lib/python3.6/site-packages/selenium-3.6.0-py3.6.egg/selenium/webdriver/remote/webdriver.py", line 308, in execute
    self.error_handler.check_response(response)
  File "/Users/lucianofeo/Desktop/golem/env/lib/python3.6/site-packages/selenium-3.6.0-py3.6.egg/selenium/webdriver/remote/errorhandler.py", line 194, in check_response
    raise exception_class(message, screen, stacktrace)
selenium.common.exceptions.UnexpectedAlertPresentException: Alert Text: None
Message: unexpected alert open: {Alert text : There are unsaved changes}
  (Session info: chrome=61.0.3163.100)
  (Driver info: chromedriver=2.32.498537 (cb2f855cbc7b82e20387eaf9a43f6b99b6105061),platform=Mac OS X 10.12.5 x86_64)


During handling of the above exception, another exception occurred:

Traceback (most recent call last):
  File "/Users/lucianofeo/Desktop/golem/src/golem/browser.py", line 19, in _find_webelement
    webelement = root.find_element_by_id(selector_value)
  File "/Users/lucianofeo/Desktop/golem/env/lib/python3.6/site-packages/selenium-3.6.0-py3.6.egg/selenium/webdriver/remote/webdriver.py", line 341, in find_element_by_id
    return self.find_element(by=By.ID, value=id_)
  File "/Users/lucianofeo/Desktop/golem/env/lib/python3.6/site-packages/selenium-3.6.0-py3.6.egg/selenium/webdriver/remote/webdriver.py", line 843, in find_element
    'value': value})['value']
  File "/Users/lucianofeo/Desktop/golem/env/lib/python3.6/site-packages/selenium-3.6.0-py3.6.egg/selenium/webdriver/remote/webdriver.py", line 308, in execute
    self.error_handler.check_response(response)
  File "/Users/lucianofeo/Desktop/golem/env/lib/python3.6/site-packages/selenium-3.6.0-py3.6.egg/selenium/webdriver/remote/errorhandler.py", line 194, in check_response
    raise exception_class(message, screen, stacktrace)
selenium.common.exceptions.UnexpectedAlertPresentException: Alert Text: None
Message: unexpected alert open: {Alert text : There are unsaved changes}
  (Session info: chrome=61.0.3163.100)
  (Driver info: chromedriver=2.32.498537 (cb2f855cbc7b82e20387eaf9a43f6b99b6105061),platform=Mac OS X 10.12.5 x86_64)


During handling of the above exception, another exception occurred:

Traceback (most recent call last):
  File "/Users/lucianofeo/Desktop/golem/src/golem/browser.py", line 19, in _find_webelement
    webelement = root.find_element_by_id(selector_value)
  File "/Users/lucianofeo/Desktop/golem/env/lib/python3.6/site-packages/selenium-3.6.0-py3.6.egg/selenium/webdriver/remote/webdriver.py", line 341, in find_element_by_id
    return self.find_element(by=By.ID, value=id_)
  File "/Users/lucianofeo/Desktop/golem/env/lib/python3.6/site-packages/selenium-3.6.0-py3.6.egg/selenium/webdriver/remote/webdriver.py", line 843, in find_element
    'value': value})['value']
  File "/Users/lucianofeo/Desktop/golem/env/lib/python3.6/site-packages/selenium-3.6.0-py3.6.egg/selenium/webdriver/remote/webdriver.py", line 308, in execute
    self.error_handler.check_response(response)
  File "/Users/lucianofeo/Desktop/golem/env/lib/python3.6/site-packages/selenium-3.6.0-py3.6.egg/selenium/webdriver/remote/errorhandler.py", line 194, in check_response
    raise exception_class(message, screen, stacktrace)
selenium.common.exceptions.UnexpectedAlertPresentException: Alert Text: None
Message: unexpected alert open: {Alert text : There are unsaved changes}
  (Session info: chrome=61.0.3163.100)
  (Driver info: chromedriver=2.32.498537 (cb2f855cbc7b82e20387eaf9a43f6b99b6105061),platform=Mac OS X 10.12.5 x86_64)


During handling of the above exception, another exception occurred:

Traceback (most recent call last):
  File "/Users/lucianofeo/Desktop/golem/src/golem/browser.py", line 19, in _find_webelement
    webelement = root.find_element_by_id(selector_value)
  File "/Users/lucianofeo/Desktop/golem/env/lib/python3.6/site-packages/selenium-3.6.0-py3.6.egg/selenium/webdriver/remote/webdriver.py", line 341, in find_element_by_id
    return self.find_element(by=By.ID, value=id_)
  File "/Users/lucianofeo/Desktop/golem/env/lib/python3.6/site-packages/selenium-3.6.0-py3.6.egg/selenium/webdriver/remote/webdriver.py", line 843, in find_element
    'value': value})['value']
  File "/Users/lucianofeo/Desktop/golem/env/lib/python3.6/site-packages/selenium-3.6.0-py3.6.egg/selenium/webdriver/remote/webdriver.py", line 308, in execute
    self.error_handler.check_response(response)
  File "/Users/lucianofeo/Desktop/golem/env/lib/python3.6/site-packages/selenium-3.6.0-py3.6.egg/selenium/webdriver/remote/errorhandler.py", line 194, in check_response
    raise exception_class(message, screen, stacktrace)
selenium.common.exceptions.UnexpectedAlertPresentException: Alert Text: None
Message: unexpected alert open: {Alert text : There are unsaved changes}
  (Session info: chrome=61.0.3163.100)
  (Driver info: chromedriver=2.32.498537 (cb2f855cbc7b82e20387eaf9a43f6b99b6105061),platform=Mac OS X 10.12.5 x86_64)


During handling of the above exception, another exception occurred:

Traceback (most recent call last):
  File "/Users/lucianofeo/Desktop/golem/src/golem/browser.py", line 19, in _find_webelement
    webelement = root.find_element_by_id(selector_value)
  File "/Users/lucianofeo/Desktop/golem/env/lib/python3.6/site-packages/selenium-3.6.0-py3.6.egg/selenium/webdriver/remote/webdriver.py", line 341, in find_element_by_id
    return self.find_element(by=By.ID, value=id_)
  File "/Users/lucianofeo/Desktop/golem/env/lib/python3.6/site-packages/selenium-3.6.0-py3.6.egg/selenium/webdriver/remote/webdriver.py", line 843, in find_element
    'value': value})['value']
  File "/Users/lucianofeo/Desktop/golem/env/lib/python3.6/site-packages/selenium-3.6.0-py3.6.egg/selenium/webdriver/remote/webdriver.py", line 308, in execute
    self.error_handler.check_response(response)
  File "/Users/lucianofeo/Desktop/golem/env/lib/python3.6/site-packages/selenium-3.6.0-py3.6.egg/selenium/webdriver/remote/errorhandler.py", line 194, in check_response
    raise exception_class(message, screen, stacktrace)
selenium.common.exceptions.UnexpectedAlertPresentException: Alert Text: None
Message: unexpected alert open: {Alert text : There are unsaved changes}
  (Session info: chrome=61.0.3163.100)
  (Driver info: chromedriver=2.32.498537 (cb2f855cbc7b82e20387eaf9a43f6b99b6105061),platform=Mac OS X 10.12.5 x86_64)


During handling of the above exception, another exception occurred:

Traceback (most recent call last):
  File "/Users/lucianofeo/Desktop/golem/src/golem/browser.py", line 19, in _find_webelement
    webelement = root.find_element_by_id(selector_value)
  File "/Users/lucianofeo/Desktop/golem/env/lib/python3.6/site-packages/selenium-3.6.0-py3.6.egg/selenium/webdriver/remote/webdriver.py", line 341, in find_element_by_id
    return self.find_element(by=By.ID, value=id_)
  File "/Users/lucianofeo/Desktop/golem/env/lib/python3.6/site-packages/selenium-3.6.0-py3.6.egg/selenium/webdriver/remote/webdriver.py", line 843, in find_element
    'value': value})['value']
  File "/Users/lucianofeo/Desktop/golem/env/lib/python3.6/site-packages/selenium-3.6.0-py3.6.egg/selenium/webdriver/remote/webdriver.py", line 308, in execute
    self.error_handler.check_response(response)
  File "/Users/lucianofeo/Desktop/golem/env/lib/python3.6/site-packages/selenium-3.6.0-py3.6.egg/selenium/webdriver/remote/errorhandler.py", line 194, in check_response
    raise exception_class(message, screen, stacktrace)
selenium.common.exceptions.UnexpectedAlertPresentException: Alert Text: None
Message: unexpected alert open: {Alert text : There are unsaved changes}
  (Session info: chrome=61.0.3163.100)
  (Driver info: chromedriver=2.32.498537 (cb2f855cbc7b82e20387eaf9a43f6b99b6105061),platform=Mac OS X 10.12.5 x86_64)


During handling of the above exception, another exception occurred:

Traceback (most recent call last):
  File "/Users/lucianofeo/Desktop/golem/src/golem/browser.py", line 19, in _find_webelement
    webelement = root.find_element_by_id(selector_value)
  File "/Users/lucianofeo/Desktop/golem/env/lib/python3.6/site-packages/selenium-3.6.0-py3.6.egg/selenium/webdriver/remote/webdriver.py", line 341, in find_element_by_id
    return self.find_element(by=By.ID, value=id_)
  File "/Users/lucianofeo/Desktop/golem/env/lib/python3.6/site-packages/selenium-3.6.0-py3.6.egg/selenium/webdriver/remote/webdriver.py", line 843, in find_element
    'value': value})['value']
  File "/Users/lucianofeo/Desktop/golem/env/lib/python3.6/site-packages/selenium-3.6.0-py3.6.egg/selenium/webdriver/remote/webdriver.py", line 308, in execute
    self.error_handler.check_response(response)
  File "/Users/lucianofeo/Desktop/golem/env/lib/python3.6/site-packages/selenium-3.6.0-py3.6.egg/selenium/webdriver/remote/errorhandler.py", line 194, in check_response
    raise exception_class(message, screen, stacktrace)
selenium.common.exceptions.UnexpectedAlertPresentException: Alert Text: None
Message: unexpected alert open: {Alert text : There are unsaved changes}
  (Session info: chrome=61.0.3163.100)
  (Driver info: chromedriver=2.32.498537 (cb2f855cbc7b82e20387eaf9a43f6b99b6105061),platform=Mac OS X 10.12.5 x86_64)


During handling of the above exception, another exception occurred:

Traceback (most recent call last):
  File "/Users/lucianofeo/Desktop/golem/src/golem/browser.py", line 19, in _find_webelement
    webelement = root.find_element_by_id(selector_value)
  File "/Users/lucianofeo/Desktop/golem/env/lib/python3.6/site-packages/selenium-3.6.0-py3.6.egg/selenium/webdriver/remote/webdriver.py", line 341, in find_element_by_id
    return self.find_element(by=By.ID, value=id_)
  File "/Users/lucianofeo/Desktop/golem/env/lib/python3.6/site-packages/selenium-3.6.0-py3.6.egg/selenium/webdriver/remote/webdriver.py", line 843, in find_element
    'value': value})['value']
  File "/Users/lucianofeo/Desktop/golem/env/lib/python3.6/site-packages/selenium-3.6.0-py3.6.egg/selenium/webdriver/remote/webdriver.py", line 308, in execute
    self.error_handler.check_response(response)
  File "/Users/lucianofeo/Desktop/golem/env/lib/python3.6/site-packages/selenium-3.6.0-py3.6.egg/selenium/webdriver/remote/errorhandler.py", line 194, in check_response
    raise exception_class(message, screen, stacktrace)
selenium.common.exceptions.UnexpectedAlertPresentException: Alert Text: None
Message: unexpected alert open: {Alert text : There are unsaved changes}
  (Session info: chrome=61.0.3163.100)
  (Driver info: chromedriver=2.32.498537 (cb2f855cbc7b82e20387eaf9a43f6b99b6105061),platform=Mac OS X 10.12.5 x86_64)


During handling of the above exception, another exception occurred:

Traceback (most recent call last):
  File "/Users/lucianofeo/Desktop/golem/src/golem/browser.py", line 19, in _find_webelement
    webelement = root.find_element_by_id(selector_value)
  File "/Users/lucianofeo/Desktop/golem/env/lib/python3.6/site-packages/selenium-3.6.0-py3.6.egg/selenium/webdriver/remote/webdriver.py", line 341, in find_element_by_id
    return self.find_element(by=By.ID, value=id_)
  File "/Users/lucianofeo/Desktop/golem/env/lib/python3.6/site-packages/selenium-3.6.0-py3.6.egg/selenium/webdriver/remote/webdriver.py", line 843, in find_element
    'value': value})['value']
  File "/Users/lucianofeo/Desktop/golem/env/lib/python3.6/site-packages/selenium-3.6.0-py3.6.egg/selenium/webdriver/remote/webdriver.py", line 308, in execute
    self.error_handler.check_response(response)
  File "/Users/lucianofeo/Desktop/golem/env/lib/python3.6/site-packages/selenium-3.6.0-py3.6.egg/selenium/webdriver/remote/errorhandler.py", line 194, in check_response
    raise exception_class(message, screen, stacktrace)
selenium.common.exceptions.UnexpectedAlertPresentException: Alert Text: None
Message: unexpected alert open: {Alert text : There are unsaved changes}
  (Session info: chrome=61.0.3163.100)
  (Driver info: chromedriver=2.32.498537 (cb2f855cbc7b82e20387eaf9a43f6b99b6105061),platform=Mac OS X 10.12.5 x86_64)


During handling of the above exception, another exception occurred:

Traceback (most recent call last):
  File "/Users/lucianofeo/Desktop/golem/src/golem/browser.py", line 19, in _find_webelement
    webelement = root.find_element_by_id(selector_value)
  File "/Users/lucianofeo/Desktop/golem/env/lib/python3.6/site-packages/selenium-3.6.0-py3.6.egg/selenium/webdriver/remote/webdriver.py", line 341, in find_element_by_id
    return self.find_element(by=By.ID, value=id_)
  File "/Users/lucianofeo/Desktop/golem/env/lib/python3.6/site-packages/selenium-3.6.0-py3.6.egg/selenium/webdriver/remote/webdriver.py", line 843, in find_element
    'value': value})['value']
  File "/Users/lucianofeo/Desktop/golem/env/lib/python3.6/site-packages/selenium-3.6.0-py3.6.egg/selenium/webdriver/remote/webdriver.py", line 308, in execute
    self.error_handler.check_response(response)
  File "/Users/lucianofeo/Desktop/golem/env/lib/python3.6/site-packages/selenium-3.6.0-py3.6.egg/selenium/webdriver/remote/errorhandler.py", line 194, in check_response
    raise exception_class(message, screen, stacktrace)
selenium.common.exceptions.UnexpectedAlertPresentException: Alert Text: None
Message: unexpected alert open: {Alert text : There are unsaved changes}
  (Session info: chrome=61.0.3163.100)
  (Driver info: chromedriver=2.32.498537 (cb2f855cbc7b82e20387eaf9a43f6b99b6105061),platform=Mac OS X 10.12.5 x86_64)


During handling of the above exception, another exception occurred:

Traceback (most recent call last):
  File "/Users/lucianofeo/Desktop/golem/src/golem/browser.py", line 19, in _find_webelement
    webelement = root.find_element_by_id(selector_value)
  File "/Users/lucianofeo/Desktop/golem/env/lib/python3.6/site-packages/selenium-3.6.0-py3.6.egg/selenium/webdriver/remote/webdriver.py", line 341, in find_element_by_id
    return self.find_element(by=By.ID, value=id_)
  File "/Users/lucianofeo/Desktop/golem/env/lib/python3.6/site-packages/selenium-3.6.0-py3.6.egg/selenium/webdriver/remote/webdriver.py", line 843, in find_element
    'value': value})['value']
  File "/Users/lucianofeo/Desktop/golem/env/lib/python3.6/site-packages/selenium-3.6.0-py3.6.egg/selenium/webdriver/remote/webdriver.py", line 308, in execute
    self.error_handler.check_response(response)
  File "/Users/lucianofeo/Desktop/golem/env/lib/python3.6/site-packages/selenium-3.6.0-py3.6.egg/selenium/webdriver/remote/errorhandler.py", line 194, in check_response
    raise exception_class(message, screen, stacktrace)
selenium.common.exceptions.UnexpectedAlertPresentException: Alert Text: None
Message: unexpected alert open: {Alert text : There are unsaved changes}
  (Session info: chrome=61.0.3163.100)
  (Driver info: chromedriver=2.32.498537 (cb2f855cbc7b82e20387eaf9a43f6b99b6105061),platform=Mac OS X 10.12.5 x86_64)


During handling of the above exception, another exception occurred:

Traceback (most recent call last):
  File "/Users/lucianofeo/Desktop/golem/src/golem/test_runner/test_runner.py", line 115, in run_test
    test_module.test(execution.data)
  File "/Users/lucianofeo/Desktop/golem/example/projects/golem/tests/test_page/add_description.py", line 20, in test
    verify_text_in_element(test_page.description, data.description)
  File "/Users/lucianofeo/Desktop/golem/src/golem/actions.py", line 366, in verify_text_in_element
    webelement = get_browser().find(element)
  File "/Users/lucianofeo/Desktop/golem/src/golem/browser.py", line 115, in _find
    element_name, timeout)
  File "/Users/lucianofeo/Desktop/golem/src/golem/browser.py", line 45, in _find_webelement
    element_name, remaining_time)
  File "/Users/lucianofeo/Desktop/golem/src/golem/browser.py", line 45, in _find_webelement
    element_name, remaining_time)
  File "/Users/lucianofeo/Desktop/golem/src/golem/browser.py", line 45, in _find_webelement
    element_name, remaining_time)
  [Previous line repeated 35 more times]
  File "/Users/lucianofeo/Desktop/golem/src/golem/browser.py", line 48, in _find_webelement
    .format(element_name, selector_type, selector_value))
golem.core.exceptions.ElementNotFound: Element description not found using selector id:'description'
22:22:32.865 INFO Close driver
