2017-10-11 19:19:06,860 golem INFO Test execution started: test_page.add_action_to_test
2017-10-11 19:19:06,861 golem INFO Browser: chrome
2017-10-11 19:19:06,861 golem INFO Environment: test
2017-10-11 19:19:06,861 golem INFO Using data: 
    action: send keys
    url: http://localhost:8000

2017-10-11 19:19:08,884 golem INFO Navigate to: 'http://localhost:8000'
2017-10-11 19:19:09,413 golem DEBUG Element not found yet, remaining time: 19.471288204193115
2017-10-11 19:19:09,921 golem DEBUG Element not found yet, remaining time: 18.964514017105103
2017-10-11 19:19:10,429 golem DEBUG Element not found yet, remaining time: 18.456748008728027
2017-10-11 19:19:10,936 golem DEBUG Element not found yet, remaining time: 17.949755907058716
2017-10-11 19:19:11,444 golem DEBUG Element not found yet, remaining time: 17.442161798477173
2017-10-11 19:19:11,951 golem DEBUG Element not found yet, remaining time: 16.935454607009888
2017-10-11 19:19:12,460 golem DEBUG Element not found yet, remaining time: 16.426806688308716
2017-10-11 19:19:12,967 golem DEBUG Element not found yet, remaining time: 15.919585704803467
2017-10-11 19:19:13,476 golem DEBUG Element not found yet, remaining time: 15.411693572998047
2017-10-11 19:19:13,982 golem DEBUG Element not found yet, remaining time: 14.905138731002808
2017-10-11 19:19:14,492 golem DEBUG Element not found yet, remaining time: 14.395946741104126
2017-10-11 19:19:14,998 golem DEBUG Element not found yet, remaining time: 13.889869928359985
2017-10-11 19:19:15,506 golem DEBUG Element not found yet, remaining time: 13.382768630981445
2017-10-11 19:19:16,015 golem DEBUG Element not found yet, remaining time: 12.874099731445312
2017-10-11 19:19:16,523 golem DEBUG Element not found yet, remaining time: 12.366167783737183
2017-10-11 19:19:17,032 golem DEBUG Element not found yet, remaining time: 11.85735273361206
2017-10-11 19:19:17,539 golem DEBUG Element not found yet, remaining time: 11.350292682647705
2017-10-11 19:19:18,047 golem DEBUG Element not found yet, remaining time: 10.842711687088013
2017-10-11 19:19:18,555 golem DEBUG Element not found yet, remaining time: 10.33510971069336
2017-10-11 19:19:19,063 golem DEBUG Element not found yet, remaining time: 9.827621698379517
2017-10-11 19:19:19,572 golem DEBUG Element not found yet, remaining time: 9.318760633468628
2017-10-11 19:19:20,083 golem DEBUG Element not found yet, remaining time: 8.808677434921265
2017-10-11 19:19:20,593 golem DEBUG Element not found yet, remaining time: 8.298896312713623
2017-10-11 19:19:21,102 golem DEBUG Element not found yet, remaining time: 7.7903430461883545
2017-10-11 19:19:21,608 golem DEBUG Element not found yet, remaining time: 7.284307956695557
2017-10-11 19:19:22,119 golem DEBUG Element not found yet, remaining time: 6.773893117904663
2017-10-11 19:19:22,626 golem DEBUG Element not found yet, remaining time: 6.267229318618774
2017-10-11 19:19:23,135 golem DEBUG Element not found yet, remaining time: 5.758986473083496
2017-10-11 19:19:23,645 golem DEBUG Element not found yet, remaining time: 5.248907566070557
2017-10-11 19:19:24,157 golem DEBUG Element not found yet, remaining time: 4.738017559051514
2017-10-11 19:19:24,666 golem DEBUG Element not found yet, remaining time: 4.228550434112549
2017-10-11 19:19:25,176 golem DEBUG Element not found yet, remaining time: 3.7196943759918213
2017-10-11 19:19:25,687 golem DEBUG Element not found yet, remaining time: 3.209324359893799
2017-10-11 19:19:26,197 golem DEBUG Element not found yet, remaining time: 2.6991994380950928
2017-10-11 19:19:26,707 golem DEBUG Element not found yet, remaining time: 2.1901702880859375
2017-10-11 19:19:27,214 golem DEBUG Element not found yet, remaining time: 1.6827919483184814
2017-10-11 19:19:27,721 golem DEBUG Element not found yet, remaining time: 1.1760520935058594
2017-10-11 19:19:28,230 golem DEBUG Element not found yet, remaining time: 0.6678931713104248
2017-10-11 19:19:28,737 golem DEBUG Element not found yet, remaining time: 0.16100120544433594
2017-10-11 19:19:29,249 golem INFO Take screenshot error
2017-10-11 19:19:29,838 golem ERROR An error ocurred:
Traceback (most recent call last):
  File "/Users/lucianofeo/Desktop/golem/src/golem/browser.py", line 19, in _find_webelement
    webelement = root.find_element_by_id(selector_value)
  File "/Users/lucianofeo/Desktop/golem/env/lib/python3.6/site-packages/selenium-3.6.0-py3.6.egg/selenium/webdriver/remote/webdriver.py", line 341, in find_element_by_id
    return self.find_element(by=By.ID, value=id_)
  File "/Users/lucianofeo/Desktop/golem/env/lib/python3.6/site-packages/selenium-3.6.0-py3.6.egg/selenium/webdriver/remote/webdriver.py", line 843, in find_element
    'value': value})['value']
  File "/Users/lucianofeo/Desktop/golem/env/lib/python3.6/site-packages/selenium-3.6.0-py3.6.egg/selenium/webdriver/remote/webdriver.py", line 308, in execute
    self.error_handler.check_response(response)
  File "/Users/lucianofeo/Desktop/golem/env/lib/python3.6/site-packages/selenium-3.6.0-py3.6.egg/selenium/webdriver/remote/errorhandler.py", line 194, in check_response
    raise exception_class(message, screen, stacktrace)
selenium.common.exceptions.NoSuchElementException: Message: no such element: Unable to locate element: {"method":"id","selector":"username"}
  (Session info: chrome=61.0.3163.100)
  (Driver info: chromedriver=2.32.498537 (cb2f855cbc7b82e20387eaf9a43f6b99b6105061),platform=Mac OS X 10.12.5 x86_64)


During handling of the above exception, another exception occurred:

Traceback (most recent call last):
  File "/Users/lucianofeo/Desktop/golem/src/golem/browser.py", line 19, in _find_webelement
    webelement = root.find_element_by_id(selector_value)
  File "/Users/lucianofeo/Desktop/golem/env/lib/python3.6/site-packages/selenium-3.6.0-py3.6.egg/selenium/webdriver/remote/webdriver.py", line 341, in find_element_by_id
    return self.find_element(by=By.ID, value=id_)
  File "/Users/lucianofeo/Desktop/golem/env/lib/python3.6/site-packages/selenium-3.6.0-py3.6.egg/selenium/webdriver/remote/webdriver.py", line 843, in find_element
    'value': value})['value']
  File "/Users/lucianofeo/Desktop/golem/env/lib/python3.6/site-packages/selenium-3.6.0-py3.6.egg/selenium/webdriver/remote/webdriver.py", line 308, in execute
    self.error_handler.check_response(response)
  File "/Users/lucianofeo/Desktop/golem/env/lib/python3.6/site-packages/selenium-3.6.0-py3.6.egg/selenium/webdriver/remote/errorhandler.py", line 194, in check_response
    raise exception_class(message, screen, stacktrace)
selenium.common.exceptions.NoSuchElementException: Message: no such element: Unable to locate element: {"method":"id","selector":"username"}
  (Session info: chrome=61.0.3163.100)
  (Driver info: chromedriver=2.32.498537 (cb2f855cbc7b82e20387eaf9a43f6b99b6105061),platform=Mac OS X 10.12.5 x86_64)


During handling of the above exception, another exception occurred:

Traceback (most recent call last):
  File "/Users/lucianofeo/Desktop/golem/src/golem/browser.py", line 19, in _find_webelement
    webelement = root.find_element_by_id(selector_value)
  File "/Users/lucianofeo/Desktop/golem/env/lib/python3.6/site-packages/selenium-3.6.0-py3.6.egg/selenium/webdriver/remote/webdriver.py", line 341, in find_element_by_id
    return self.find_element(by=By.ID, value=id_)
  File "/Users/lucianofeo/Desktop/golem/env/lib/python3.6/site-packages/selenium-3.6.0-py3.6.egg/selenium/webdriver/remote/webdriver.py", line 843, in find_element
    'value': value})['value']
  File "/Users/lucianofeo/Desktop/golem/env/lib/python3.6/site-packages/selenium-3.6.0-py3.6.egg/selenium/webdriver/remote/webdriver.py", line 308, in execute
    self.error_handler.check_response(response)
  File "/Users/lucianofeo/Desktop/golem/env/lib/python3.6/site-packages/selenium-3.6.0-py3.6.egg/selenium/webdriver/remote/errorhandler.py", line 194, in check_response
    raise exception_class(message, screen, stacktrace)
selenium.common.exceptions.NoSuchElementException: Message: no such element: Unable to locate element: {"method":"id","selector":"username"}
  (Session info: chrome=61.0.3163.100)
  (Driver info: chromedriver=2.32.498537 (cb2f855cbc7b82e20387eaf9a43f6b99b6105061),platform=Mac OS X 10.12.5 x86_64)


During handling of the above exception, another exception occurred:

Traceback (most recent call last):
  File "/Users/lucianofeo/Desktop/golem/src/golem/browser.py", line 19, in _find_webelement
    webelement = root.find_element_by_id(selector_value)
  File "/Users/lucianofeo/Desktop/golem/env/lib/python3.6/site-packages/selenium-3.6.0-py3.6.egg/selenium/webdriver/remote/webdriver.py", line 341, in find_element_by_id
    return self.find_element(by=By.ID, value=id_)
  File "/Users/lucianofeo/Desktop/golem/env/lib/python3.6/site-packages/selenium-3.6.0-py3.6.egg/selenium/webdriver/remote/webdriver.py", line 843, in find_element
    'value': value})['value']
  File "/Users/lucianofeo/Desktop/golem/env/lib/python3.6/site-packages/selenium-3.6.0-py3.6.egg/selenium/webdriver/remote/webdriver.py", line 308, in execute
    self.error_handler.check_response(response)
  File "/Users/lucianofeo/Desktop/golem/env/lib/python3.6/site-packages/selenium-3.6.0-py3.6.egg/selenium/webdriver/remote/errorhandler.py", line 194, in check_response
    raise exception_class(message, screen, stacktrace)
selenium.common.exceptions.NoSuchElementException: Message: no such element: Unable to locate element: {"method":"id","selector":"username"}
  (Session info: chrome=61.0.3163.100)
  (Driver info: chromedriver=2.32.498537 (cb2f855cbc7b82e20387eaf9a43f6b99b6105061),platform=Mac OS X 10.12.5 x86_64)


During handling of the above exception, another exception occurred:

Traceback (most recent call last):
  File "/Users/lucianofeo/Desktop/golem/src/golem/browser.py", line 19, in _find_webelement
    webelement = root.find_element_by_id(selector_value)
  File "/Users/lucianofeo/Desktop/golem/env/lib/python3.6/site-packages/selenium-3.6.0-py3.6.egg/selenium/webdriver/remote/webdriver.py", line 341, in find_element_by_id
    return self.find_element(by=By.ID, value=id_)
  File "/Users/lucianofeo/Desktop/golem/env/lib/python3.6/site-packages/selenium-3.6.0-py3.6.egg/selenium/webdriver/remote/webdriver.py", line 843, in find_element
    'value': value})['value']
  File "/Users/lucianofeo/Desktop/golem/env/lib/python3.6/site-packages/selenium-3.6.0-py3.6.egg/selenium/webdriver/remote/webdriver.py", line 308, in execute
    self.error_handler.check_response(response)
  File "/Users/lucianofeo/Desktop/golem/env/lib/python3.6/site-packages/selenium-3.6.0-py3.6.egg/selenium/webdriver/remote/errorhandler.py", line 194, in check_response
    raise exception_class(message, screen, stacktrace)
selenium.common.exceptions.NoSuchElementException: Message: no such element: Unable to locate element: {"method":"id","selector":"username"}
  (Session info: chrome=61.0.3163.100)
  (Driver info: chromedriver=2.32.498537 (cb2f855cbc7b82e20387eaf9a43f6b99b6105061),platform=Mac OS X 10.12.5 x86_64)


During handling of the above exception, another exception occurred:

Traceback (most recent call last):
  File "/Users/lucianofeo/Desktop/golem/src/golem/browser.py", line 19, in _find_webelement
    webelement = root.find_element_by_id(selector_value)
  File "/Users/lucianofeo/Desktop/golem/env/lib/python3.6/site-packages/selenium-3.6.0-py3.6.egg/selenium/webdriver/remote/webdriver.py", line 341, in find_element_by_id
    return self.find_element(by=By.ID, value=id_)
  File "/Users/lucianofeo/Desktop/golem/env/lib/python3.6/site-packages/selenium-3.6.0-py3.6.egg/selenium/webdriver/remote/webdriver.py", line 843, in find_element
    'value': value})['value']
  File "/Users/lucianofeo/Desktop/golem/env/lib/python3.6/site-packages/selenium-3.6.0-py3.6.egg/selenium/webdriver/remote/webdriver.py", line 308, in execute
    self.error_handler.check_response(response)
  File "/Users/lucianofeo/Desktop/golem/env/lib/python3.6/site-packages/selenium-3.6.0-py3.6.egg/selenium/webdriver/remote/errorhandler.py", line 194, in check_response
    raise exception_class(message, screen, stacktrace)
selenium.common.exceptions.NoSuchElementException: Message: no such element: Unable to locate element: {"method":"id","selector":"username"}
  (Session info: chrome=61.0.3163.100)
  (Driver info: chromedriver=2.32.498537 (cb2f855cbc7b82e20387eaf9a43f6b99b6105061),platform=Mac OS X 10.12.5 x86_64)


During handling of the above exception, another exception occurred:

Traceback (most recent call last):
  File "/Users/lucianofeo/Desktop/golem/src/golem/browser.py", line 19, in _find_webelement
    webelement = root.find_element_by_id(selector_value)
  File "/Users/lucianofeo/Desktop/golem/env/lib/python3.6/site-packages/selenium-3.6.0-py3.6.egg/selenium/webdriver/remote/webdriver.py", line 341, in find_element_by_id
    return self.find_element(by=By.ID, value=id_)
  File "/Users/lucianofeo/Desktop/golem/env/lib/python3.6/site-packages/selenium-3.6.0-py3.6.egg/selenium/webdriver/remote/webdriver.py", line 843, in find_element
    'value': value})['value']
  File "/Users/lucianofeo/Desktop/golem/env/lib/python3.6/site-packages/selenium-3.6.0-py3.6.egg/selenium/webdriver/remote/webdriver.py", line 308, in execute
    self.error_handler.check_response(response)
  File "/Users/lucianofeo/Desktop/golem/env/lib/python3.6/site-packages/selenium-3.6.0-py3.6.egg/selenium/webdriver/remote/errorhandler.py", line 194, in check_response
    raise exception_class(message, screen, stacktrace)
selenium.common.exceptions.NoSuchElementException: Message: no such element: Unable to locate element: {"method":"id","selector":"username"}
  (Session info: chrome=61.0.3163.100)
  (Driver info: chromedriver=2.32.498537 (cb2f855cbc7b82e20387eaf9a43f6b99b6105061),platform=Mac OS X 10.12.5 x86_64)


During handling of the above exception, another exception occurred:

Traceback (most recent call last):
  File "/Users/lucianofeo/Desktop/golem/src/golem/browser.py", line 19, in _find_webelement
    webelement = root.find_element_by_id(selector_value)
  File "/Users/lucianofeo/Desktop/golem/env/lib/python3.6/site-packages/selenium-3.6.0-py3.6.egg/selenium/webdriver/remote/webdriver.py", line 341, in find_element_by_id
    return self.find_element(by=By.ID, value=id_)
  File "/Users/lucianofeo/Desktop/golem/env/lib/python3.6/site-packages/selenium-3.6.0-py3.6.egg/selenium/webdriver/remote/webdriver.py", line 843, in find_element
    'value': value})['value']
  File "/Users/lucianofeo/Desktop/golem/env/lib/python3.6/site-packages/selenium-3.6.0-py3.6.egg/selenium/webdriver/remote/webdriver.py", line 308, in execute
    self.error_handler.check_response(response)
  File "/Users/lucianofeo/Desktop/golem/env/lib/python3.6/site-packages/selenium-3.6.0-py3.6.egg/selenium/webdriver/remote/errorhandler.py", line 194, in check_response
    raise exception_class(message, screen, stacktrace)
selenium.common.exceptions.NoSuchElementException: Message: no such element: Unable to locate element: {"method":"id","selector":"username"}
  (Session info: chrome=61.0.3163.100)
  (Driver info: chromedriver=2.32.498537 (cb2f855cbc7b82e20387eaf9a43f6b99b6105061),platform=Mac OS X 10.12.5 x86_64)


During handling of the above exception, another exception occurred:

Traceback (most recent call last):
  File "/Users/lucianofeo/Desktop/golem/src/golem/browser.py", line 19, in _find_webelement
    webelement = root.find_element_by_id(selector_value)
  File "/Users/lucianofeo/Desktop/golem/env/lib/python3.6/site-packages/selenium-3.6.0-py3.6.egg/selenium/webdriver/remote/webdriver.py", line 341, in find_element_by_id
    return self.find_element(by=By.ID, value=id_)
  File "/Users/lucianofeo/Desktop/golem/env/lib/python3.6/site-packages/selenium-3.6.0-py3.6.egg/selenium/webdriver/remote/webdriver.py", line 843, in find_element
    'value': value})['value']
  File "/Users/lucianofeo/Desktop/golem/env/lib/python3.6/site-packages/selenium-3.6.0-py3.6.egg/selenium/webdriver/remote/webdriver.py", line 308, in execute
    self.error_handler.check_response(response)
  File "/Users/lucianofeo/Desktop/golem/env/lib/python3.6/site-packages/selenium-3.6.0-py3.6.egg/selenium/webdriver/remote/errorhandler.py", line 194, in check_response
    raise exception_class(message, screen, stacktrace)
selenium.common.exceptions.NoSuchElementException: Message: no such element: Unable to locate element: {"method":"id","selector":"username"}
  (Session info: chrome=61.0.3163.100)
  (Driver info: chromedriver=2.32.498537 (cb2f855cbc7b82e20387eaf9a43f6b99b6105061),platform=Mac OS X 10.12.5 x86_64)


During handling of the above exception, another exception occurred:

Traceback (most recent call last):
  File "/Users/lucianofeo/Desktop/golem/src/golem/browser.py", line 19, in _find_webelement
    webelement = root.find_element_by_id(selector_value)
  File "/Users/lucianofeo/Desktop/golem/env/lib/python3.6/site-packages/selenium-3.6.0-py3.6.egg/selenium/webdriver/remote/webdriver.py", line 341, in find_element_by_id
    return self.find_element(by=By.ID, value=id_)
  File "/Users/lucianofeo/Desktop/golem/env/lib/python3.6/site-packages/selenium-3.6.0-py3.6.egg/selenium/webdriver/remote/webdriver.py", line 843, in find_element
    'value': value})['value']
  File "/Users/lucianofeo/Desktop/golem/env/lib/python3.6/site-packages/selenium-3.6.0-py3.6.egg/selenium/webdriver/remote/webdriver.py", line 308, in execute
    self.error_handler.check_response(response)
  File "/Users/lucianofeo/Desktop/golem/env/lib/python3.6/site-packages/selenium-3.6.0-py3.6.egg/selenium/webdriver/remote/errorhandler.py", line 194, in check_response
    raise exception_class(message, screen, stacktrace)
selenium.common.exceptions.NoSuchElementException: Message: no such element: Unable to locate element: {"method":"id","selector":"username"}
  (Session info: chrome=61.0.3163.100)
  (Driver info: chromedriver=2.32.498537 (cb2f855cbc7b82e20387eaf9a43f6b99b6105061),platform=Mac OS X 10.12.5 x86_64)


During handling of the above exception, another exception occurred:

Traceback (most recent call last):
  File "/Users/lucianofeo/Desktop/golem/src/golem/browser.py", line 19, in _find_webelement
    webelement = root.find_element_by_id(selector_value)
  File "/Users/lucianofeo/Desktop/golem/env/lib/python3.6/site-packages/selenium-3.6.0-py3.6.egg/selenium/webdriver/remote/webdriver.py", line 341, in find_element_by_id
    return self.find_element(by=By.ID, value=id_)
  File "/Users/lucianofeo/Desktop/golem/env/lib/python3.6/site-packages/selenium-3.6.0-py3.6.egg/selenium/webdriver/remote/webdriver.py", line 843, in find_element
    'value': value})['value']
  File "/Users/lucianofeo/Desktop/golem/env/lib/python3.6/site-packages/selenium-3.6.0-py3.6.egg/selenium/webdriver/remote/webdriver.py", line 308, in execute
    self.error_handler.check_response(response)
  File "/Users/lucianofeo/Desktop/golem/env/lib/python3.6/site-packages/selenium-3.6.0-py3.6.egg/selenium/webdriver/remote/errorhandler.py", line 194, in check_response
    raise exception_class(message, screen, stacktrace)
selenium.common.exceptions.NoSuchElementException: Message: no such element: Unable to locate element: {"method":"id","selector":"username"}
  (Session info: chrome=61.0.3163.100)
  (Driver info: chromedriver=2.32.498537 (cb2f855cbc7b82e20387eaf9a43f6b99b6105061),platform=Mac OS X 10.12.5 x86_64)


During handling of the above exception, another exception occurred:

Traceback (most recent call last):
  File "/Users/lucianofeo/Desktop/golem/src/golem/browser.py", line 19, in _find_webelement
    webelement = root.find_element_by_id(selector_value)
  File "/Users/lucianofeo/Desktop/golem/env/lib/python3.6/site-packages/selenium-3.6.0-py3.6.egg/selenium/webdriver/remote/webdriver.py", line 341, in find_element_by_id
    return self.find_element(by=By.ID, value=id_)
  File "/Users/lucianofeo/Desktop/golem/env/lib/python3.6/site-packages/selenium-3.6.0-py3.6.egg/selenium/webdriver/remote/webdriver.py", line 843, in find_element
    'value': value})['value']
  File "/Users/lucianofeo/Desktop/golem/env/lib/python3.6/site-packages/selenium-3.6.0-py3.6.egg/selenium/webdriver/remote/webdriver.py", line 308, in execute
    self.error_handler.check_response(response)
  File "/Users/lucianofeo/Desktop/golem/env/lib/python3.6/site-packages/selenium-3.6.0-py3.6.egg/selenium/webdriver/remote/errorhandler.py", line 194, in check_response
    raise exception_class(message, screen, stacktrace)
selenium.common.exceptions.NoSuchElementException: Message: no such element: Unable to locate element: {"method":"id","selector":"username"}
  (Session info: chrome=61.0.3163.100)
  (Driver info: chromedriver=2.32.498537 (cb2f855cbc7b82e20387eaf9a43f6b99b6105061),platform=Mac OS X 10.12.5 x86_64)


During handling of the above exception, another exception occurred:

Traceback (most recent call last):
  File "/Users/lucianofeo/Desktop/golem/src/golem/browser.py", line 19, in _find_webelement
    webelement = root.find_element_by_id(selector_value)
  File "/Users/lucianofeo/Desktop/golem/env/lib/python3.6/site-packages/selenium-3.6.0-py3.6.egg/selenium/webdriver/remote/webdriver.py", line 341, in find_element_by_id
    return self.find_element(by=By.ID, value=id_)
  File "/Users/lucianofeo/Desktop/golem/env/lib/python3.6/site-packages/selenium-3.6.0-py3.6.egg/selenium/webdriver/remote/webdriver.py", line 843, in find_element
    'value': value})['value']
  File "/Users/lucianofeo/Desktop/golem/env/lib/python3.6/site-packages/selenium-3.6.0-py3.6.egg/selenium/webdriver/remote/webdriver.py", line 308, in execute
    self.error_handler.check_response(response)
  File "/Users/lucianofeo/Desktop/golem/env/lib/python3.6/site-packages/selenium-3.6.0-py3.6.egg/selenium/webdriver/remote/errorhandler.py", line 194, in check_response
    raise exception_class(message, screen, stacktrace)
selenium.common.exceptions.NoSuchElementException: Message: no such element: Unable to locate element: {"method":"id","selector":"username"}
  (Session info: chrome=61.0.3163.100)
  (Driver info: chromedriver=2.32.498537 (cb2f855cbc7b82e20387eaf9a43f6b99b6105061),platform=Mac OS X 10.12.5 x86_64)


During handling of the above exception, another exception occurred:

Traceback (most recent call last):
  File "/Users/lucianofeo/Desktop/golem/src/golem/browser.py", line 19, in _find_webelement
    webelement = root.find_element_by_id(selector_value)
  File "/Users/lucianofeo/Desktop/golem/env/lib/python3.6/site-packages/selenium-3.6.0-py3.6.egg/selenium/webdriver/remote/webdriver.py", line 341, in find_element_by_id
    return self.find_element(by=By.ID, value=id_)
  File "/Users/lucianofeo/Desktop/golem/env/lib/python3.6/site-packages/selenium-3.6.0-py3.6.egg/selenium/webdriver/remote/webdriver.py", line 843, in find_element
    'value': value})['value']
  File "/Users/lucianofeo/Desktop/golem/env/lib/python3.6/site-packages/selenium-3.6.0-py3.6.egg/selenium/webdriver/remote/webdriver.py", line 308, in execute
    self.error_handler.check_response(response)
  File "/Users/lucianofeo/Desktop/golem/env/lib/python3.6/site-packages/selenium-3.6.0-py3.6.egg/selenium/webdriver/remote/errorhandler.py", line 194, in check_response
    raise exception_class(message, screen, stacktrace)
selenium.common.exceptions.NoSuchElementException: Message: no such element: Unable to locate element: {"method":"id","selector":"username"}
  (Session info: chrome=61.0.3163.100)
  (Driver info: chromedriver=2.32.498537 (cb2f855cbc7b82e20387eaf9a43f6b99b6105061),platform=Mac OS X 10.12.5 x86_64)


During handling of the above exception, another exception occurred:

Traceback (most recent call last):
  File "/Users/lucianofeo/Desktop/golem/src/golem/browser.py", line 19, in _find_webelement
    webelement = root.find_element_by_id(selector_value)
  File "/Users/lucianofeo/Desktop/golem/env/lib/python3.6/site-packages/selenium-3.6.0-py3.6.egg/selenium/webdriver/remote/webdriver.py", line 341, in find_element_by_id
    return self.find_element(by=By.ID, value=id_)
  File "/Users/lucianofeo/Desktop/golem/env/lib/python3.6/site-packages/selenium-3.6.0-py3.6.egg/selenium/webdriver/remote/webdriver.py", line 843, in find_element
    'value': value})['value']
  File "/Users/lucianofeo/Desktop/golem/env/lib/python3.6/site-packages/selenium-3.6.0-py3.6.egg/selenium/webdriver/remote/webdriver.py", line 308, in execute
    self.error_handler.check_response(response)
  File "/Users/lucianofeo/Desktop/golem/env/lib/python3.6/site-packages/selenium-3.6.0-py3.6.egg/selenium/webdriver/remote/errorhandler.py", line 194, in check_response
    raise exception_class(message, screen, stacktrace)
selenium.common.exceptions.NoSuchElementException: Message: no such element: Unable to locate element: {"method":"id","selector":"username"}
  (Session info: chrome=61.0.3163.100)
  (Driver info: chromedriver=2.32.498537 (cb2f855cbc7b82e20387eaf9a43f6b99b6105061),platform=Mac OS X 10.12.5 x86_64)


During handling of the above exception, another exception occurred:

Traceback (most recent call last):
  File "/Users/lucianofeo/Desktop/golem/src/golem/browser.py", line 19, in _find_webelement
    webelement = root.find_element_by_id(selector_value)
  File "/Users/lucianofeo/Desktop/golem/env/lib/python3.6/site-packages/selenium-3.6.0-py3.6.egg/selenium/webdriver/remote/webdriver.py", line 341, in find_element_by_id
    return self.find_element(by=By.ID, value=id_)
  File "/Users/lucianofeo/Desktop/golem/env/lib/python3.6/site-packages/selenium-3.6.0-py3.6.egg/selenium/webdriver/remote/webdriver.py", line 843, in find_element
    'value': value})['value']
  File "/Users/lucianofeo/Desktop/golem/env/lib/python3.6/site-packages/selenium-3.6.0-py3.6.egg/selenium/webdriver/remote/webdriver.py", line 308, in execute
    self.error_handler.check_response(response)
  File "/Users/lucianofeo/Desktop/golem/env/lib/python3.6/site-packages/selenium-3.6.0-py3.6.egg/selenium/webdriver/remote/errorhandler.py", line 194, in check_response
    raise exception_class(message, screen, stacktrace)
selenium.common.exceptions.NoSuchElementException: Message: no such element: Unable to locate element: {"method":"id","selector":"username"}
  (Session info: chrome=61.0.3163.100)
  (Driver info: chromedriver=2.32.498537 (cb2f855cbc7b82e20387eaf9a43f6b99b6105061),platform=Mac OS X 10.12.5 x86_64)


During handling of the above exception, another exception occurred:

Traceback (most recent call last):
  File "/Users/lucianofeo/Desktop/golem/src/golem/browser.py", line 19, in _find_webelement
    webelement = root.find_element_by_id(selector_value)
  File "/Users/lucianofeo/Desktop/golem/env/lib/python3.6/site-packages/selenium-3.6.0-py3.6.egg/selenium/webdriver/remote/webdriver.py", line 341, in find_element_by_id
    return self.find_element(by=By.ID, value=id_)
  File "/Users/lucianofeo/Desktop/golem/env/lib/python3.6/site-packages/selenium-3.6.0-py3.6.egg/selenium/webdriver/remote/webdriver.py", line 843, in find_element
    'value': value})['value']
  File "/Users/lucianofeo/Desktop/golem/env/lib/python3.6/site-packages/selenium-3.6.0-py3.6.egg/selenium/webdriver/remote/webdriver.py", line 308, in execute
    self.error_handler.check_response(response)
  File "/Users/lucianofeo/Desktop/golem/env/lib/python3.6/site-packages/selenium-3.6.0-py3.6.egg/selenium/webdriver/remote/errorhandler.py", line 194, in check_response
    raise exception_class(message, screen, stacktrace)
selenium.common.exceptions.NoSuchElementException: Message: no such element: Unable to locate element: {"method":"id","selector":"username"}
  (Session info: chrome=61.0.3163.100)
  (Driver info: chromedriver=2.32.498537 (cb2f855cbc7b82e20387eaf9a43f6b99b6105061),platform=Mac OS X 10.12.5 x86_64)


During handling of the above exception, another exception occurred:

Traceback (most recent call last):
  File "/Users/lucianofeo/Desktop/golem/src/golem/browser.py", line 19, in _find_webelement
    webelement = root.find_element_by_id(selector_value)
  File "/Users/lucianofeo/Desktop/golem/env/lib/python3.6/site-packages/selenium-3.6.0-py3.6.egg/selenium/webdriver/remote/webdriver.py", line 341, in find_element_by_id
    return self.find_element(by=By.ID, value=id_)
  File "/Users/lucianofeo/Desktop/golem/env/lib/python3.6/site-packages/selenium-3.6.0-py3.6.egg/selenium/webdriver/remote/webdriver.py", line 843, in find_element
    'value': value})['value']
  File "/Users/lucianofeo/Desktop/golem/env/lib/python3.6/site-packages/selenium-3.6.0-py3.6.egg/selenium/webdriver/remote/webdriver.py", line 308, in execute
    self.error_handler.check_response(response)
  File "/Users/lucianofeo/Desktop/golem/env/lib/python3.6/site-packages/selenium-3.6.0-py3.6.egg/selenium/webdriver/remote/errorhandler.py", line 194, in check_response
    raise exception_class(message, screen, stacktrace)
selenium.common.exceptions.NoSuchElementException: Message: no such element: Unable to locate element: {"method":"id","selector":"username"}
  (Session info: chrome=61.0.3163.100)
  (Driver info: chromedriver=2.32.498537 (cb2f855cbc7b82e20387eaf9a43f6b99b6105061),platform=Mac OS X 10.12.5 x86_64)


During handling of the above exception, another exception occurred:

Traceback (most recent call last):
  File "/Users/lucianofeo/Desktop/golem/src/golem/browser.py", line 19, in _find_webelement
    webelement = root.find_element_by_id(selector_value)
  File "/Users/lucianofeo/Desktop/golem/env/lib/python3.6/site-packages/selenium-3.6.0-py3.6.egg/selenium/webdriver/remote/webdriver.py", line 341, in find_element_by_id
    return self.find_element(by=By.ID, value=id_)
  File "/Users/lucianofeo/Desktop/golem/env/lib/python3.6/site-packages/selenium-3.6.0-py3.6.egg/selenium/webdriver/remote/webdriver.py", line 843, in find_element
    'value': value})['value']
  File "/Users/lucianofeo/Desktop/golem/env/lib/python3.6/site-packages/selenium-3.6.0-py3.6.egg/selenium/webdriver/remote/webdriver.py", line 308, in execute
    self.error_handler.check_response(response)
  File "/Users/lucianofeo/Desktop/golem/env/lib/python3.6/site-packages/selenium-3.6.0-py3.6.egg/selenium/webdriver/remote/errorhandler.py", line 194, in check_response
    raise exception_class(message, screen, stacktrace)
selenium.common.exceptions.NoSuchElementException: Message: no such element: Unable to locate element: {"method":"id","selector":"username"}
  (Session info: chrome=61.0.3163.100)
  (Driver info: chromedriver=2.32.498537 (cb2f855cbc7b82e20387eaf9a43f6b99b6105061),platform=Mac OS X 10.12.5 x86_64)


During handling of the above exception, another exception occurred:

Traceback (most recent call last):
  File "/Users/lucianofeo/Desktop/golem/src/golem/browser.py", line 19, in _find_webelement
    webelement = root.find_element_by_id(selector_value)
  File "/Users/lucianofeo/Desktop/golem/env/lib/python3.6/site-packages/selenium-3.6.0-py3.6.egg/selenium/webdriver/remote/webdriver.py", line 341, in find_element_by_id
    return self.find_element(by=By.ID, value=id_)
  File "/Users/lucianofeo/Desktop/golem/env/lib/python3.6/site-packages/selenium-3.6.0-py3.6.egg/selenium/webdriver/remote/webdriver.py", line 843, in find_element
    'value': value})['value']
  File "/Users/lucianofeo/Desktop/golem/env/lib/python3.6/site-packages/selenium-3.6.0-py3.6.egg/selenium/webdriver/remote/webdriver.py", line 308, in execute
    self.error_handler.check_response(response)
  File "/Users/lucianofeo/Desktop/golem/env/lib/python3.6/site-packages/selenium-3.6.0-py3.6.egg/selenium/webdriver/remote/errorhandler.py", line 194, in check_response
    raise exception_class(message, screen, stacktrace)
selenium.common.exceptions.NoSuchElementException: Message: no such element: Unable to locate element: {"method":"id","selector":"username"}
  (Session info: chrome=61.0.3163.100)
  (Driver info: chromedriver=2.32.498537 (cb2f855cbc7b82e20387eaf9a43f6b99b6105061),platform=Mac OS X 10.12.5 x86_64)


During handling of the above exception, another exception occurred:

Traceback (most recent call last):
  File "/Users/lucianofeo/Desktop/golem/src/golem/browser.py", line 19, in _find_webelement
    webelement = root.find_element_by_id(selector_value)
  File "/Users/lucianofeo/Desktop/golem/env/lib/python3.6/site-packages/selenium-3.6.0-py3.6.egg/selenium/webdriver/remote/webdriver.py", line 341, in find_element_by_id
    return self.find_element(by=By.ID, value=id_)
  File "/Users/lucianofeo/Desktop/golem/env/lib/python3.6/site-packages/selenium-3.6.0-py3.6.egg/selenium/webdriver/remote/webdriver.py", line 843, in find_element
    'value': value})['value']
  File "/Users/lucianofeo/Desktop/golem/env/lib/python3.6/site-packages/selenium-3.6.0-py3.6.egg/selenium/webdriver/remote/webdriver.py", line 308, in execute
    self.error_handler.check_response(response)
  File "/Users/lucianofeo/Desktop/golem/env/lib/python3.6/site-packages/selenium-3.6.0-py3.6.egg/selenium/webdriver/remote/errorhandler.py", line 194, in check_response
    raise exception_class(message, screen, stacktrace)
selenium.common.exceptions.NoSuchElementException: Message: no such element: Unable to locate element: {"method":"id","selector":"username"}
  (Session info: chrome=61.0.3163.100)
  (Driver info: chromedriver=2.32.498537 (cb2f855cbc7b82e20387eaf9a43f6b99b6105061),platform=Mac OS X 10.12.5 x86_64)


During handling of the above exception, another exception occurred:

Traceback (most recent call last):
  File "/Users/lucianofeo/Desktop/golem/src/golem/browser.py", line 19, in _find_webelement
    webelement = root.find_element_by_id(selector_value)
  File "/Users/lucianofeo/Desktop/golem/env/lib/python3.6/site-packages/selenium-3.6.0-py3.6.egg/selenium/webdriver/remote/webdriver.py", line 341, in find_element_by_id
    return self.find_element(by=By.ID, value=id_)
  File "/Users/lucianofeo/Desktop/golem/env/lib/python3.6/site-packages/selenium-3.6.0-py3.6.egg/selenium/webdriver/remote/webdriver.py", line 843, in find_element
    'value': value})['value']
  File "/Users/lucianofeo/Desktop/golem/env/lib/python3.6/site-packages/selenium-3.6.0-py3.6.egg/selenium/webdriver/remote/webdriver.py", line 308, in execute
    self.error_handler.check_response(response)
  File "/Users/lucianofeo/Desktop/golem/env/lib/python3.6/site-packages/selenium-3.6.0-py3.6.egg/selenium/webdriver/remote/errorhandler.py", line 194, in check_response
    raise exception_class(message, screen, stacktrace)
selenium.common.exceptions.NoSuchElementException: Message: no such element: Unable to locate element: {"method":"id","selector":"username"}
  (Session info: chrome=61.0.3163.100)
  (Driver info: chromedriver=2.32.498537 (cb2f855cbc7b82e20387eaf9a43f6b99b6105061),platform=Mac OS X 10.12.5 x86_64)


During handling of the above exception, another exception occurred:

Traceback (most recent call last):
  File "/Users/lucianofeo/Desktop/golem/src/golem/browser.py", line 19, in _find_webelement
    webelement = root.find_element_by_id(selector_value)
  File "/Users/lucianofeo/Desktop/golem/env/lib/python3.6/site-packages/selenium-3.6.0-py3.6.egg/selenium/webdriver/remote/webdriver.py", line 341, in find_element_by_id
    return self.find_element(by=By.ID, value=id_)
  File "/Users/lucianofeo/Desktop/golem/env/lib/python3.6/site-packages/selenium-3.6.0-py3.6.egg/selenium/webdriver/remote/webdriver.py", line 843, in find_element
    'value': value})['value']
  File "/Users/lucianofeo/Desktop/golem/env/lib/python3.6/site-packages/selenium-3.6.0-py3.6.egg/selenium/webdriver/remote/webdriver.py", line 308, in execute
    self.error_handler.check_response(response)
  File "/Users/lucianofeo/Desktop/golem/env/lib/python3.6/site-packages/selenium-3.6.0-py3.6.egg/selenium/webdriver/remote/errorhandler.py", line 194, in check_response
    raise exception_class(message, screen, stacktrace)
selenium.common.exceptions.NoSuchElementException: Message: no such element: Unable to locate element: {"method":"id","selector":"username"}
  (Session info: chrome=61.0.3163.100)
  (Driver info: chromedriver=2.32.498537 (cb2f855cbc7b82e20387eaf9a43f6b99b6105061),platform=Mac OS X 10.12.5 x86_64)


During handling of the above exception, another exception occurred:

Traceback (most recent call last):
  File "/Users/lucianofeo/Desktop/golem/src/golem/browser.py", line 19, in _find_webelement
    webelement = root.find_element_by_id(selector_value)
  File "/Users/lucianofeo/Desktop/golem/env/lib/python3.6/site-packages/selenium-3.6.0-py3.6.egg/selenium/webdriver/remote/webdriver.py", line 341, in find_element_by_id
    return self.find_element(by=By.ID, value=id_)
  File "/Users/lucianofeo/Desktop/golem/env/lib/python3.6/site-packages/selenium-3.6.0-py3.6.egg/selenium/webdriver/remote/webdriver.py", line 843, in find_element
    'value': value})['value']
  File "/Users/lucianofeo/Desktop/golem/env/lib/python3.6/site-packages/selenium-3.6.0-py3.6.egg/selenium/webdriver/remote/webdriver.py", line 308, in execute
    self.error_handler.check_response(response)
  File "/Users/lucianofeo/Desktop/golem/env/lib/python3.6/site-packages/selenium-3.6.0-py3.6.egg/selenium/webdriver/remote/errorhandler.py", line 194, in check_response
    raise exception_class(message, screen, stacktrace)
selenium.common.exceptions.NoSuchElementException: Message: no such element: Unable to locate element: {"method":"id","selector":"username"}
  (Session info: chrome=61.0.3163.100)
  (Driver info: chromedriver=2.32.498537 (cb2f855cbc7b82e20387eaf9a43f6b99b6105061),platform=Mac OS X 10.12.5 x86_64)


During handling of the above exception, another exception occurred:

Traceback (most recent call last):
  File "/Users/lucianofeo/Desktop/golem/src/golem/browser.py", line 19, in _find_webelement
    webelement = root.find_element_by_id(selector_value)
  File "/Users/lucianofeo/Desktop/golem/env/lib/python3.6/site-packages/selenium-3.6.0-py3.6.egg/selenium/webdriver/remote/webdriver.py", line 341, in find_element_by_id
    return self.find_element(by=By.ID, value=id_)
  File "/Users/lucianofeo/Desktop/golem/env/lib/python3.6/site-packages/selenium-3.6.0-py3.6.egg/selenium/webdriver/remote/webdriver.py", line 843, in find_element
    'value': value})['value']
  File "/Users/lucianofeo/Desktop/golem/env/lib/python3.6/site-packages/selenium-3.6.0-py3.6.egg/selenium/webdriver/remote/webdriver.py", line 308, in execute
    self.error_handler.check_response(response)
  File "/Users/lucianofeo/Desktop/golem/env/lib/python3.6/site-packages/selenium-3.6.0-py3.6.egg/selenium/webdriver/remote/errorhandler.py", line 194, in check_response
    raise exception_class(message, screen, stacktrace)
selenium.common.exceptions.NoSuchElementException: Message: no such element: Unable to locate element: {"method":"id","selector":"username"}
  (Session info: chrome=61.0.3163.100)
  (Driver info: chromedriver=2.32.498537 (cb2f855cbc7b82e20387eaf9a43f6b99b6105061),platform=Mac OS X 10.12.5 x86_64)


During handling of the above exception, another exception occurred:

Traceback (most recent call last):
  File "/Users/lucianofeo/Desktop/golem/src/golem/browser.py", line 19, in _find_webelement
    webelement = root.find_element_by_id(selector_value)
  File "/Users/lucianofeo/Desktop/golem/env/lib/python3.6/site-packages/selenium-3.6.0-py3.6.egg/selenium/webdriver/remote/webdriver.py", line 341, in find_element_by_id
    return self.find_element(by=By.ID, value=id_)
  File "/Users/lucianofeo/Desktop/golem/env/lib/python3.6/site-packages/selenium-3.6.0-py3.6.egg/selenium/webdriver/remote/webdriver.py", line 843, in find_element
    'value': value})['value']
  File "/Users/lucianofeo/Desktop/golem/env/lib/python3.6/site-packages/selenium-3.6.0-py3.6.egg/selenium/webdriver/remote/webdriver.py", line 308, in execute
    self.error_handler.check_response(response)
  File "/Users/lucianofeo/Desktop/golem/env/lib/python3.6/site-packages/selenium-3.6.0-py3.6.egg/selenium/webdriver/remote/errorhandler.py", line 194, in check_response
    raise exception_class(message, screen, stacktrace)
selenium.common.exceptions.NoSuchElementException: Message: no such element: Unable to locate element: {"method":"id","selector":"username"}
  (Session info: chrome=61.0.3163.100)
  (Driver info: chromedriver=2.32.498537 (cb2f855cbc7b82e20387eaf9a43f6b99b6105061),platform=Mac OS X 10.12.5 x86_64)


During handling of the above exception, another exception occurred:

Traceback (most recent call last):
  File "/Users/lucianofeo/Desktop/golem/src/golem/browser.py", line 19, in _find_webelement
    webelement = root.find_element_by_id(selector_value)
  File "/Users/lucianofeo/Desktop/golem/env/lib/python3.6/site-packages/selenium-3.6.0-py3.6.egg/selenium/webdriver/remote/webdriver.py", line 341, in find_element_by_id
    return self.find_element(by=By.ID, value=id_)
  File "/Users/lucianofeo/Desktop/golem/env/lib/python3.6/site-packages/selenium-3.6.0-py3.6.egg/selenium/webdriver/remote/webdriver.py", line 843, in find_element
    'value': value})['value']
  File "/Users/lucianofeo/Desktop/golem/env/lib/python3.6/site-packages/selenium-3.6.0-py3.6.egg/selenium/webdriver/remote/webdriver.py", line 308, in execute
    self.error_handler.check_response(response)
  File "/Users/lucianofeo/Desktop/golem/env/lib/python3.6/site-packages/selenium-3.6.0-py3.6.egg/selenium/webdriver/remote/errorhandler.py", line 194, in check_response
    raise exception_class(message, screen, stacktrace)
selenium.common.exceptions.NoSuchElementException: Message: no such element: Unable to locate element: {"method":"id","selector":"username"}
  (Session info: chrome=61.0.3163.100)
  (Driver info: chromedriver=2.32.498537 (cb2f855cbc7b82e20387eaf9a43f6b99b6105061),platform=Mac OS X 10.12.5 x86_64)


During handling of the above exception, another exception occurred:

Traceback (most recent call last):
  File "/Users/lucianofeo/Desktop/golem/src/golem/browser.py", line 19, in _find_webelement
    webelement = root.find_element_by_id(selector_value)
  File "/Users/lucianofeo/Desktop/golem/env/lib/python3.6/site-packages/selenium-3.6.0-py3.6.egg/selenium/webdriver/remote/webdriver.py", line 341, in find_element_by_id
    return self.find_element(by=By.ID, value=id_)
  File "/Users/lucianofeo/Desktop/golem/env/lib/python3.6/site-packages/selenium-3.6.0-py3.6.egg/selenium/webdriver/remote/webdriver.py", line 843, in find_element
    'value': value})['value']
  File "/Users/lucianofeo/Desktop/golem/env/lib/python3.6/site-packages/selenium-3.6.0-py3.6.egg/selenium/webdriver/remote/webdriver.py", line 308, in execute
    self.error_handler.check_response(response)
  File "/Users/lucianofeo/Desktop/golem/env/lib/python3.6/site-packages/selenium-3.6.0-py3.6.egg/selenium/webdriver/remote/errorhandler.py", line 194, in check_response
    raise exception_class(message, screen, stacktrace)
selenium.common.exceptions.NoSuchElementException: Message: no such element: Unable to locate element: {"method":"id","selector":"username"}
  (Session info: chrome=61.0.3163.100)
  (Driver info: chromedriver=2.32.498537 (cb2f855cbc7b82e20387eaf9a43f6b99b6105061),platform=Mac OS X 10.12.5 x86_64)


During handling of the above exception, another exception occurred:

Traceback (most recent call last):
  File "/Users/lucianofeo/Desktop/golem/src/golem/browser.py", line 19, in _find_webelement
    webelement = root.find_element_by_id(selector_value)
  File "/Users/lucianofeo/Desktop/golem/env/lib/python3.6/site-packages/selenium-3.6.0-py3.6.egg/selenium/webdriver/remote/webdriver.py", line 341, in find_element_by_id
    return self.find_element(by=By.ID, value=id_)
  File "/Users/lucianofeo/Desktop/golem/env/lib/python3.6/site-packages/selenium-3.6.0-py3.6.egg/selenium/webdriver/remote/webdriver.py", line 843, in find_element
    'value': value})['value']
  File "/Users/lucianofeo/Desktop/golem/env/lib/python3.6/site-packages/selenium-3.6.0-py3.6.egg/selenium/webdriver/remote/webdriver.py", line 308, in execute
    self.error_handler.check_response(response)
  File "/Users/lucianofeo/Desktop/golem/env/lib/python3.6/site-packages/selenium-3.6.0-py3.6.egg/selenium/webdriver/remote/errorhandler.py", line 194, in check_response
    raise exception_class(message, screen, stacktrace)
selenium.common.exceptions.NoSuchElementException: Message: no such element: Unable to locate element: {"method":"id","selector":"username"}
  (Session info: chrome=61.0.3163.100)
  (Driver info: chromedriver=2.32.498537 (cb2f855cbc7b82e20387eaf9a43f6b99b6105061),platform=Mac OS X 10.12.5 x86_64)


During handling of the above exception, another exception occurred:

Traceback (most recent call last):
  File "/Users/lucianofeo/Desktop/golem/src/golem/browser.py", line 19, in _find_webelement
    webelement = root.find_element_by_id(selector_value)
  File "/Users/lucianofeo/Desktop/golem/env/lib/python3.6/site-packages/selenium-3.6.0-py3.6.egg/selenium/webdriver/remote/webdriver.py", line 341, in find_element_by_id
    return self.find_element(by=By.ID, value=id_)
  File "/Users/lucianofeo/Desktop/golem/env/lib/python3.6/site-packages/selenium-3.6.0-py3.6.egg/selenium/webdriver/remote/webdriver.py", line 843, in find_element
    'value': value})['value']
  File "/Users/lucianofeo/Desktop/golem/env/lib/python3.6/site-packages/selenium-3.6.0-py3.6.egg/selenium/webdriver/remote/webdriver.py", line 308, in execute
    self.error_handler.check_response(response)
  File "/Users/lucianofeo/Desktop/golem/env/lib/python3.6/site-packages/selenium-3.6.0-py3.6.egg/selenium/webdriver/remote/errorhandler.py", line 194, in check_response
    raise exception_class(message, screen, stacktrace)
selenium.common.exceptions.NoSuchElementException: Message: no such element: Unable to locate element: {"method":"id","selector":"username"}
  (Session info: chrome=61.0.3163.100)
  (Driver info: chromedriver=2.32.498537 (cb2f855cbc7b82e20387eaf9a43f6b99b6105061),platform=Mac OS X 10.12.5 x86_64)


During handling of the above exception, another exception occurred:

Traceback (most recent call last):
  File "/Users/lucianofeo/Desktop/golem/src/golem/browser.py", line 19, in _find_webelement
    webelement = root.find_element_by_id(selector_value)
  File "/Users/lucianofeo/Desktop/golem/env/lib/python3.6/site-packages/selenium-3.6.0-py3.6.egg/selenium/webdriver/remote/webdriver.py", line 341, in find_element_by_id
    return self.find_element(by=By.ID, value=id_)
  File "/Users/lucianofeo/Desktop/golem/env/lib/python3.6/site-packages/selenium-3.6.0-py3.6.egg/selenium/webdriver/remote/webdriver.py", line 843, in find_element
    'value': value})['value']
  File "/Users/lucianofeo/Desktop/golem/env/lib/python3.6/site-packages/selenium-3.6.0-py3.6.egg/selenium/webdriver/remote/webdriver.py", line 308, in execute
    self.error_handler.check_response(response)
  File "/Users/lucianofeo/Desktop/golem/env/lib/python3.6/site-packages/selenium-3.6.0-py3.6.egg/selenium/webdriver/remote/errorhandler.py", line 194, in check_response
    raise exception_class(message, screen, stacktrace)
selenium.common.exceptions.NoSuchElementException: Message: no such element: Unable to locate element: {"method":"id","selector":"username"}
  (Session info: chrome=61.0.3163.100)
  (Driver info: chromedriver=2.32.498537 (cb2f855cbc7b82e20387eaf9a43f6b99b6105061),platform=Mac OS X 10.12.5 x86_64)


During handling of the above exception, another exception occurred:

Traceback (most recent call last):
  File "/Users/lucianofeo/Desktop/golem/src/golem/browser.py", line 19, in _find_webelement
    webelement = root.find_element_by_id(selector_value)
  File "/Users/lucianofeo/Desktop/golem/env/lib/python3.6/site-packages/selenium-3.6.0-py3.6.egg/selenium/webdriver/remote/webdriver.py", line 341, in find_element_by_id
    return self.find_element(by=By.ID, value=id_)
  File "/Users/lucianofeo/Desktop/golem/env/lib/python3.6/site-packages/selenium-3.6.0-py3.6.egg/selenium/webdriver/remote/webdriver.py", line 843, in find_element
    'value': value})['value']
  File "/Users/lucianofeo/Desktop/golem/env/lib/python3.6/site-packages/selenium-3.6.0-py3.6.egg/selenium/webdriver/remote/webdriver.py", line 308, in execute
    self.error_handler.check_response(response)
  File "/Users/lucianofeo/Desktop/golem/env/lib/python3.6/site-packages/selenium-3.6.0-py3.6.egg/selenium/webdriver/remote/errorhandler.py", line 194, in check_response
    raise exception_class(message, screen, stacktrace)
selenium.common.exceptions.NoSuchElementException: Message: no such element: Unable to locate element: {"method":"id","selector":"username"}
  (Session info: chrome=61.0.3163.100)
  (Driver info: chromedriver=2.32.498537 (cb2f855cbc7b82e20387eaf9a43f6b99b6105061),platform=Mac OS X 10.12.5 x86_64)


During handling of the above exception, another exception occurred:

Traceback (most recent call last):
  File "/Users/lucianofeo/Desktop/golem/src/golem/browser.py", line 19, in _find_webelement
    webelement = root.find_element_by_id(selector_value)
  File "/Users/lucianofeo/Desktop/golem/env/lib/python3.6/site-packages/selenium-3.6.0-py3.6.egg/selenium/webdriver/remote/webdriver.py", line 341, in find_element_by_id
    return self.find_element(by=By.ID, value=id_)
  File "/Users/lucianofeo/Desktop/golem/env/lib/python3.6/site-packages/selenium-3.6.0-py3.6.egg/selenium/webdriver/remote/webdriver.py", line 843, in find_element
    'value': value})['value']
  File "/Users/lucianofeo/Desktop/golem/env/lib/python3.6/site-packages/selenium-3.6.0-py3.6.egg/selenium/webdriver/remote/webdriver.py", line 308, in execute
    self.error_handler.check_response(response)
  File "/Users/lucianofeo/Desktop/golem/env/lib/python3.6/site-packages/selenium-3.6.0-py3.6.egg/selenium/webdriver/remote/errorhandler.py", line 194, in check_response
    raise exception_class(message, screen, stacktrace)
selenium.common.exceptions.NoSuchElementException: Message: no such element: Unable to locate element: {"method":"id","selector":"username"}
  (Session info: chrome=61.0.3163.100)
  (Driver info: chromedriver=2.32.498537 (cb2f855cbc7b82e20387eaf9a43f6b99b6105061),platform=Mac OS X 10.12.5 x86_64)


During handling of the above exception, another exception occurred:

Traceback (most recent call last):
  File "/Users/lucianofeo/Desktop/golem/src/golem/browser.py", line 19, in _find_webelement
    webelement = root.find_element_by_id(selector_value)
  File "/Users/lucianofeo/Desktop/golem/env/lib/python3.6/site-packages/selenium-3.6.0-py3.6.egg/selenium/webdriver/remote/webdriver.py", line 341, in find_element_by_id
    return self.find_element(by=By.ID, value=id_)
  File "/Users/lucianofeo/Desktop/golem/env/lib/python3.6/site-packages/selenium-3.6.0-py3.6.egg/selenium/webdriver/remote/webdriver.py", line 843, in find_element
    'value': value})['value']
  File "/Users/lucianofeo/Desktop/golem/env/lib/python3.6/site-packages/selenium-3.6.0-py3.6.egg/selenium/webdriver/remote/webdriver.py", line 308, in execute
    self.error_handler.check_response(response)
  File "/Users/lucianofeo/Desktop/golem/env/lib/python3.6/site-packages/selenium-3.6.0-py3.6.egg/selenium/webdriver/remote/errorhandler.py", line 194, in check_response
    raise exception_class(message, screen, stacktrace)
selenium.common.exceptions.NoSuchElementException: Message: no such element: Unable to locate element: {"method":"id","selector":"username"}
  (Session info: chrome=61.0.3163.100)
  (Driver info: chromedriver=2.32.498537 (cb2f855cbc7b82e20387eaf9a43f6b99b6105061),platform=Mac OS X 10.12.5 x86_64)


During handling of the above exception, another exception occurred:

Traceback (most recent call last):
  File "/Users/lucianofeo/Desktop/golem/src/golem/browser.py", line 19, in _find_webelement
    webelement = root.find_element_by_id(selector_value)
  File "/Users/lucianofeo/Desktop/golem/env/lib/python3.6/site-packages/selenium-3.6.0-py3.6.egg/selenium/webdriver/remote/webdriver.py", line 341, in find_element_by_id
    return self.find_element(by=By.ID, value=id_)
  File "/Users/lucianofeo/Desktop/golem/env/lib/python3.6/site-packages/selenium-3.6.0-py3.6.egg/selenium/webdriver/remote/webdriver.py", line 843, in find_element
    'value': value})['value']
  File "/Users/lucianofeo/Desktop/golem/env/lib/python3.6/site-packages/selenium-3.6.0-py3.6.egg/selenium/webdriver/remote/webdriver.py", line 308, in execute
    self.error_handler.check_response(response)
  File "/Users/lucianofeo/Desktop/golem/env/lib/python3.6/site-packages/selenium-3.6.0-py3.6.egg/selenium/webdriver/remote/errorhandler.py", line 194, in check_response
    raise exception_class(message, screen, stacktrace)
selenium.common.exceptions.NoSuchElementException: Message: no such element: Unable to locate element: {"method":"id","selector":"username"}
  (Session info: chrome=61.0.3163.100)
  (Driver info: chromedriver=2.32.498537 (cb2f855cbc7b82e20387eaf9a43f6b99b6105061),platform=Mac OS X 10.12.5 x86_64)


During handling of the above exception, another exception occurred:

Traceback (most recent call last):
  File "/Users/lucianofeo/Desktop/golem/src/golem/browser.py", line 19, in _find_webelement
    webelement = root.find_element_by_id(selector_value)
  File "/Users/lucianofeo/Desktop/golem/env/lib/python3.6/site-packages/selenium-3.6.0-py3.6.egg/selenium/webdriver/remote/webdriver.py", line 341, in find_element_by_id
    return self.find_element(by=By.ID, value=id_)
  File "/Users/lucianofeo/Desktop/golem/env/lib/python3.6/site-packages/selenium-3.6.0-py3.6.egg/selenium/webdriver/remote/webdriver.py", line 843, in find_element
    'value': value})['value']
  File "/Users/lucianofeo/Desktop/golem/env/lib/python3.6/site-packages/selenium-3.6.0-py3.6.egg/selenium/webdriver/remote/webdriver.py", line 308, in execute
    self.error_handler.check_response(response)
  File "/Users/lucianofeo/Desktop/golem/env/lib/python3.6/site-packages/selenium-3.6.0-py3.6.egg/selenium/webdriver/remote/errorhandler.py", line 194, in check_response
    raise exception_class(message, screen, stacktrace)
selenium.common.exceptions.NoSuchElementException: Message: no such element: Unable to locate element: {"method":"id","selector":"username"}
  (Session info: chrome=61.0.3163.100)
  (Driver info: chromedriver=2.32.498537 (cb2f855cbc7b82e20387eaf9a43f6b99b6105061),platform=Mac OS X 10.12.5 x86_64)


During handling of the above exception, another exception occurred:

Traceback (most recent call last):
  File "/Users/lucianofeo/Desktop/golem/src/golem/browser.py", line 19, in _find_webelement
    webelement = root.find_element_by_id(selector_value)
  File "/Users/lucianofeo/Desktop/golem/env/lib/python3.6/site-packages/selenium-3.6.0-py3.6.egg/selenium/webdriver/remote/webdriver.py", line 341, in find_element_by_id
    return self.find_element(by=By.ID, value=id_)
  File "/Users/lucianofeo/Desktop/golem/env/lib/python3.6/site-packages/selenium-3.6.0-py3.6.egg/selenium/webdriver/remote/webdriver.py", line 843, in find_element
    'value': value})['value']
  File "/Users/lucianofeo/Desktop/golem/env/lib/python3.6/site-packages/selenium-3.6.0-py3.6.egg/selenium/webdriver/remote/webdriver.py", line 308, in execute
    self.error_handler.check_response(response)
  File "/Users/lucianofeo/Desktop/golem/env/lib/python3.6/site-packages/selenium-3.6.0-py3.6.egg/selenium/webdriver/remote/errorhandler.py", line 194, in check_response
    raise exception_class(message, screen, stacktrace)
selenium.common.exceptions.NoSuchElementException: Message: no such element: Unable to locate element: {"method":"id","selector":"username"}
  (Session info: chrome=61.0.3163.100)
  (Driver info: chromedriver=2.32.498537 (cb2f855cbc7b82e20387eaf9a43f6b99b6105061),platform=Mac OS X 10.12.5 x86_64)


During handling of the above exception, another exception occurred:

Traceback (most recent call last):
  File "/Users/lucianofeo/Desktop/golem/src/golem/browser.py", line 19, in _find_webelement
    webelement = root.find_element_by_id(selector_value)
  File "/Users/lucianofeo/Desktop/golem/env/lib/python3.6/site-packages/selenium-3.6.0-py3.6.egg/selenium/webdriver/remote/webdriver.py", line 341, in find_element_by_id
    return self.find_element(by=By.ID, value=id_)
  File "/Users/lucianofeo/Desktop/golem/env/lib/python3.6/site-packages/selenium-3.6.0-py3.6.egg/selenium/webdriver/remote/webdriver.py", line 843, in find_element
    'value': value})['value']
  File "/Users/lucianofeo/Desktop/golem/env/lib/python3.6/site-packages/selenium-3.6.0-py3.6.egg/selenium/webdriver/remote/webdriver.py", line 308, in execute
    self.error_handler.check_response(response)
  File "/Users/lucianofeo/Desktop/golem/env/lib/python3.6/site-packages/selenium-3.6.0-py3.6.egg/selenium/webdriver/remote/errorhandler.py", line 194, in check_response
    raise exception_class(message, screen, stacktrace)
selenium.common.exceptions.NoSuchElementException: Message: no such element: Unable to locate element: {"method":"id","selector":"username"}
  (Session info: chrome=61.0.3163.100)
  (Driver info: chromedriver=2.32.498537 (cb2f855cbc7b82e20387eaf9a43f6b99b6105061),platform=Mac OS X 10.12.5 x86_64)


During handling of the above exception, another exception occurred:

Traceback (most recent call last):
  File "/Users/lucianofeo/Desktop/golem/src/golem/browser.py", line 19, in _find_webelement
    webelement = root.find_element_by_id(selector_value)
  File "/Users/lucianofeo/Desktop/golem/env/lib/python3.6/site-packages/selenium-3.6.0-py3.6.egg/selenium/webdriver/remote/webdriver.py", line 341, in find_element_by_id
    return self.find_element(by=By.ID, value=id_)
  File "/Users/lucianofeo/Desktop/golem/env/lib/python3.6/site-packages/selenium-3.6.0-py3.6.egg/selenium/webdriver/remote/webdriver.py", line 843, in find_element
    'value': value})['value']
  File "/Users/lucianofeo/Desktop/golem/env/lib/python3.6/site-packages/selenium-3.6.0-py3.6.egg/selenium/webdriver/remote/webdriver.py", line 308, in execute
    self.error_handler.check_response(response)
  File "/Users/lucianofeo/Desktop/golem/env/lib/python3.6/site-packages/selenium-3.6.0-py3.6.egg/selenium/webdriver/remote/errorhandler.py", line 194, in check_response
    raise exception_class(message, screen, stacktrace)
selenium.common.exceptions.NoSuchElementException: Message: no such element: Unable to locate element: {"method":"id","selector":"username"}
  (Session info: chrome=61.0.3163.100)
  (Driver info: chromedriver=2.32.498537 (cb2f855cbc7b82e20387eaf9a43f6b99b6105061),platform=Mac OS X 10.12.5 x86_64)


During handling of the above exception, another exception occurred:

Traceback (most recent call last):
  File "/Users/lucianofeo/Desktop/golem/src/golem/browser.py", line 19, in _find_webelement
    webelement = root.find_element_by_id(selector_value)
  File "/Users/lucianofeo/Desktop/golem/env/lib/python3.6/site-packages/selenium-3.6.0-py3.6.egg/selenium/webdriver/remote/webdriver.py", line 341, in find_element_by_id
    return self.find_element(by=By.ID, value=id_)
  File "/Users/lucianofeo/Desktop/golem/env/lib/python3.6/site-packages/selenium-3.6.0-py3.6.egg/selenium/webdriver/remote/webdriver.py", line 843, in find_element
    'value': value})['value']
  File "/Users/lucianofeo/Desktop/golem/env/lib/python3.6/site-packages/selenium-3.6.0-py3.6.egg/selenium/webdriver/remote/webdriver.py", line 308, in execute
    self.error_handler.check_response(response)
  File "/Users/lucianofeo/Desktop/golem/env/lib/python3.6/site-packages/selenium-3.6.0-py3.6.egg/selenium/webdriver/remote/errorhandler.py", line 194, in check_response
    raise exception_class(message, screen, stacktrace)
selenium.common.exceptions.NoSuchElementException: Message: no such element: Unable to locate element: {"method":"id","selector":"username"}
  (Session info: chrome=61.0.3163.100)
  (Driver info: chromedriver=2.32.498537 (cb2f855cbc7b82e20387eaf9a43f6b99b6105061),platform=Mac OS X 10.12.5 x86_64)


During handling of the above exception, another exception occurred:

Traceback (most recent call last):
  File "/Users/lucianofeo/Desktop/golem/src/golem/test_runner/test_runner.py", line 109, in run_test
    test_module.setup(execution.data)
  File "/Users/lucianofeo/Desktop/golem/example/projects/golem/tests/test_page/add_action_to_test.py", line 11, in setup
    login.do_login('admin', 'admin')
  File "/Users/lucianofeo/Desktop/golem/example/projects/golem/pages/login.py", line 14, in do_login
    actions.send_keys(username_input, username)
  File "/Users/lucianofeo/Desktop/golem/src/golem/actions.py", line 226, in send_keys
    webelement = get_browser().find(element)
  File "/Users/lucianofeo/Desktop/golem/src/golem/browser.py", line 114, in _find
    element_name, timeout)
  File "/Users/lucianofeo/Desktop/golem/src/golem/browser.py", line 45, in _find_webelement
    element_name, remaining_time)
  File "/Users/lucianofeo/Desktop/golem/src/golem/browser.py", line 45, in _find_webelement
    element_name, remaining_time)
  File "/Users/lucianofeo/Desktop/golem/src/golem/browser.py", line 45, in _find_webelement
    element_name, remaining_time)
  [Previous line repeated 35 more times]
  File "/Users/lucianofeo/Desktop/golem/src/golem/browser.py", line 48, in _find_webelement
    .format(element_name, selector_type, selector_value))
golem.core.exceptions.ElementNotFound: Element username not found using selector id:'username'
2017-10-11 19:19:29,864 golem INFO Close driver
